Workbook
Name tbl_Application_domain: [1]TablesLookup!$A$2:$A$8
Name tbl_AppraisalArtifacts: [2]Tables!$AL$5:$AL$10
Name tbl_Business_Category: [3]TableLookup!$A$11:$A$15
Name tbl_CMMI_models: [3]TableLookup!$A$22:$A$25
Name tbl_COI: [2]Tables!$AF$5:$AF$19
Name tbl_CollectionApproach: [2]Tables!$R$5:$R$7
Name tbl_collectiontechnique: [2]Tables!$T$5:$T$11
Name tbl_constraints: [2]Tables!$AB$5:$AB$11
Name tbl_country: [2]Tables!$B$5:$B$258
Name tbl_Day_of_week: [3]TableLookup!$C$2:$D$8
Name tbl_equipment: [2]Tables!$Z$5:$Z$17
Name tbl_followon: [2]Tables!$AH$5:$AH$9
Name tbl_isic: [2]Tables!$D$5:$D$92
Name tbl_logisticalRequirement: [2]Tables!$X$5:$X$9
Name tbl_modelview: [2]Tables!$H$5:$H$9
Name tbl_PAcount: [2]Tables!$U$36:$Z$56
Name tbl_practiceCharacterization: Tables!$B$2:$B$6
Name tbl_practiceCharacterization: [4]Tables!$B$2:$B$6
Name tbl_practiceCharacterization: [4]Tables!$B$2:$B$6
Name tbl_practiceCharacterization: [4]Tables!$B$2:$B$6
Name tbl_practiceCharacterization: [4]Tables!$B$2:$B$6
Name tbl_practiceCharacterization: [4]Tables!$B$2:$B$6
Name tbl_practiceCharacterization: [4]Tables!$B$2:$B$6
Name tbl_practiceCharacterization: #REF!
Name tbl_practiceGroupRated: Tables!$B$9:$B$11
Name tbl_practiceGroupRated: [4]Tables!$B$9:$B$11
Name tbl_practiceGroupRated: [4]Tables!$B$9:$B$11
Name tbl_practiceGroupRated: [4]Tables!$B$9:$B$11
Name tbl_practiceGroupRated: [4]Tables!$B$9:$B$11
Name tbl_practiceGroupRated: [4]Tables!$B$9:$B$11
Name tbl_practiceGroupRated: [4]Tables!$B$9:$B$11
Name tbl_practiceGroupRated: #REF!
Name tbl_projectNames: '[2]Project&Support'!$A$3:$B$59
Name tbl_reportingRelationship: [2]Tables!$AJ$5:$AJ$10
Name tbl_responsibleEntity: [2]Tables!$V$5:$V$9
Name tbl_riskCategory: [2]Tables!$AD$5:$AD$11
Name tbl_RolePAlookup: [2]StaffGuide!$A$3:$V$13
Name tbl_sampling: [2]Tables!$L$5:$L$10
Name tbl_Staff: Tables!$D$16:$D$38
Name tbl_StaffRole: Tables!$H$16:$H$26
Name tbl_StaffRoleX: Tables!$E$16:$H$26
Name tbl_StaffX: Tables!$A$16:$D$37
Name tbl_target: [2]Tables!$F$5:$F$9
Name tbl_TaskCodeX: Tables!$I$16:$L$26
Name tbl_TaskStatusX: Tables!$M$16:$P$19
Name tbl_timezone: [2]Tables!$N$5:$N$143
Name tbl_WorkTaskCode: Tables!$L$16:$L$26
Name tbl_WorkTaskStatus: Tables!$P$16:$P$19

Sheet Tools
B2: https://www.whatismyip.com/
B3: https://www.microsoft.com/en-us/sql-server/sql-server-downloads
B5: Characterisation and filtering
B10: PAs: | C10: RDM, TS, PI, VV, PR, CM, EST, PLAN, MC, RSK, PCM, PAD, MPM, CAR, OT, PQA, DAR, GOV, II
D12: Summarise at levels
D14: Summarise at PA level
D16: Summarise at Process level
D18: Summarise at PA instantiation level
D21: Clear all filters
D23: Clear all Level characterisations
D25: Set levels = 's'
D27: Set levels = 'FM'
D29: Clear PAs
D31: Set PA's = 'FM'
D33: Clear instantiations
B36: NOTE: KEEP SPACE BETWEEN PA AND x.y, for example CAR 1.1 (NOT CAR1.1)
B37: https://docs.microsoft.com/en-us/sql/connect/oledb/download-oledb-driver-for-sql-server?view=sql-server-ver15
B38: https://go.microsoft.com/fwlink/?linkid=866658
B39: https://translate.google.com/?sl=auto&tl=en&op=translate
B40: https://www.onlinedoctranslator.com/en/translationform
B41: TV sheets

Sheet TV_TS
A1: TS - TECHNICAL SOLUTION (TS)
A2: Intent | E2: Design and build solutions that meet customer requirements.
A3: Value | E3: Provides a cost-effective design and solution that meets customer requirements and reduces rework.
E4: Level 1 | F4: Level 2 | I4: Level 3
E5: some measurement in place | F5: achieve full intent; use local measures to analyse performance / data stored / actions taken | I5: use organisational standards and tailoring; contribute improvements; set performance objectives; proactive not reactive
E6: TS 1.1 | F6: TS 2.1 | G6: TS 2.2 | H6: TS 2.3 | I6: TS 3.1 | J6: TS 3.2 | K6: TS 3.3 | L6: TS 3.4 | M6: TS 3.5 | N6: TS 3.6
A7: Practices | E7: Build solution to meet requirements. | F7: Design and build a solution to meet requirements. | G7: Evaluate the design and address identified issues. | H7: Provide guidance on use of the solution. | I7: Develop criteria for design decisions. | J7: Develop alternative solutions for selected components. | K7: Perform a build, buy, or reuse analysis. | L7: Select solutions based on design criteria. | M7: Develop, keep updated, and use information needed to implement the design. | N7: Design solution interfaces or connections using established criteria.
A8: Example Work Products | E8: product or service; | F8: architecture; component design (preliminary and detailed); completed solution; | G8: design evaluation issues; design review meeting minutes; updated design; updated solution; | H8: guidance material; | I8: design criteria (cost, complexity, time, technology, resources, performance, etc.) | J8: alternative solutions; | K8: build, buy or re-use analysis; | L8: recorded solutions, evaluations and rationale; | M8: technical data package requirements, design, test and traceability information; | N8: interface or connection - specification criteria (safety, security, performance etc); - design specification; - control documents; rationale for design selection;
A9: Example Activities | E9: build a solution; | F9: define the architecture; identify, develop or acquire effective design methods or tools; evaluate COTS products; develop a preliminary design; develop a detailed design; track requirements against design; build the solution; | G9: determine what types of reviews to perform; identify review participants; send draft designs to reviewers; conduct technical review; record decisions, issues and concerns; identify potential fixes; communicate issues and decisions; update the design; review the solution; revise components as necessary; | H9: develop and provide guidance material; | I9: analyse, develop, evaluate, use, update design criteria; review and revise design criteria with stakeholders; | J9: develop, identify, record alternative solutions; record requirements allocation for each alternative; communicate results; | K9: perform a build buy or re-use analysis; record analysis and communicate results; | L9: evaluate alternatives against criteria; select solutions that satisfy criteria; reassess and update criteria when necessary; develop, use and update records of evaluations; | M9: record the information needed to implement the solution; revise information as needed; | N9: define interface or connection criteria; develop design alternatives; identify internal and external interfaces or connections; identify interfaces or connections between components and related processes; identify user interfaces or connections; record, update, use, communicate the criteria, design and selection rationale;
A10: Standard Questions - explain how / what ? ... | F10: - Describe how you design and build a solution to meet the requirements? | G10: - How do you evaluate the designs and how do you address identified issues? | H10: - What guidance material do you provide on the use of the solution? | I10: - What criteria do you develop for design decisions? | J10: - What alternative solutions for selected components do you make? | K10: - How do you perform, build, buy or re-use decisions? | L10: - How do you use criteria to select your solutions? How do you select the solutions using the criteria? | M10: - What do you develop, keep updated, and use as the information needed to implement the design? | N10: How do you design solution interfaces (or connections) using established criteria?
A11: Questions | F11: 如何设计和构建能够满足需求的解决方案？ | G11: 如何评估设计并解决已识别的问题？ | H11: 提供了哪些解决方案的使用指南？ | I11: 会制定哪些设计决策标准？ | J11: 会制定哪些针对选定组件的备选解决方案？ | K11: 如何执行构建、采购或复用分析？ | L11: 如何使用设计标准选择解决方案？ | M11: 如何制定、保持更新并采用实现设计所需的信息？ | N11: 如何使用既定标准来设计解决方案的接口或连接？
A15: Name | B15: link | C15: engl | D15: \PAs | E15: TS 1.1 | F15: TS 2.1 | G15: TS 2.2 | H15: TS 2.3 | I15: TS 3.1 | J15: TS 3.2 | K15: TS 3.3 | L15: TS 3.4 | M15: TS 3.5 | N15: TS 3.6
A16: atm to complete | B16: link | C16: =HYPERLINK("02-项目级\P2-Qcubic to MySQL数据同步工具 V1.0\01-生存周期\05-设计\01-概要设计书(QCUBIC-SJTB-TS-BD)V1.0-engl.docx", "engl") -> engl | E16: x | F16: x | G16: x | I16: x | J16: x | K16: x | L16: x | M16: x | N16: x
A17: atm to complete | B17: link | C17: =HYPERLINK("02-项目级\P2-Qcubic to MySQL数据同步工具 V1.0\01-生存周期\05-设计\03-详细设计说明书(QCUBIC-SJTB-TS-DD)V1.0-engl.docx", "engl") -> engl | E17: x | F17: x | G17: x | I17: x | J17: x | K17: x | L17: x | M17: x | N17: x
A18: atm to complete | B18: link | C18: =HYPERLINK("02-项目级\P2-Qcubic to MySQL数据同步工具 V1.0\02-全程管理\05-评审管理\05-设计评审\01-概要设计说明书\05-评审报告_概要设计书(QCUBIC-SJTB-PR-ReviewRpt)V1.1-engl.xlsx", "engl") -> engl | G18: x
A19: atm to complete | B19: link | C19: =HYPERLINK("02-项目级\P2-Qcubic to MySQL数据同步工具 V1.0\02-全程管理\05-评审管理\05-设计评审\02-详细设计说明书\05-评审报告_详细设计(QCUBIC-SJTB-PR-ReviewRpt)V1.1-engl.xlsx", "engl") -> engl | G19: x
A20: atm to complete | B20: link | C20: =HYPERLINK("02-项目级\P2-Qcubic to MySQL数据同步工具 V1.0\01-生存周期\05-设计\04-用户手册(QCUBIC-SJTB-TS-Tem-UserMPMnual)V1.0-engl.docx", "engl") -> engl | H20: x
A21: atm to complete | B21: link | C21: =HYPERLINK("01-组织级\01-组织财富库\01-标准过程文件库\02-软件工程规范\03-设计\设计过程文件(QCUBIC-SPI-TS-Proc-Design)V1.2-engl.docx", "engl") -> engl | I21: x
A22: atm to complete | B22: link | C22: =HYPERLINK("02-项目级\P2-Qcubic to MySQL数据同步工具 V1.0\02-全程管理\04-决策分析\01-决策分析报告（QCUBIC-SJTB-dar-evaluaterpt)V1.0-engl.xlsx", "engl") -> engl | J22: x | L22: x
A23: atm to complete | B23: link | C23: =HYPERLINK("02-项目级\P2-Qcubic to MySQL数据同步工具 V1.0\01-生存周期\05-设计\05-购买,复用,自制评价表(QCUBIC-SJTB-TS-Purchase, reuse, self-made evaluation)V1.0-engl.xlsx", "engl") -> engl | K23: x
A24: atm to complete | B24: link | C24: =HYPERLINK("01-组织级\01-组织财富库\01-标准过程文件库\02-软件工程规范\03-设计\设计规范(QCUBIC-SPI-TS-Std-Design)V1.2-engl.docx", "engl") -> engl | N24: x
A25: atm to complete | B25: link | C25: =HYPERLINK("01-组织级\01-组织财富库\01-标准过程文件库\02-软件工程规范\03-设计\设计指南(QCUBIC-SPI-TS-Guid-Design)V1.2-engl.docx", "engl") -> engl | N25: x

Sheet TV_PI
A1: PI - PRODUCT INTEGRATION (PI)
A2: Intent | E2: Integrate and deliver the solution that addresses functionality and quality requirements.
A3: Value | E3: Increases customers' satisfaction by giving them a solution that meets or exceeds their functionality and quality requirements.
E4: Level 1 | F4: Level 2 | L4: Level 3
E5: some measurement in place | F5: achieve full intent; use local measures to analyse performance / data stored / actions taken | L5: use organisational standards and tailoring; contribute improvements; set performance objectives; proactive not reactive
E6: PI 1.1 | F6: PI 2.1 | G6: PI 2.2 | H6: PI 2.3 | I6: PI 2.4 | J6: PI 2.5 | K6: PI 2.6 | L6: PI 3.1 | M6: PI 3.2 | N6: PI 3.3
A7: Practices | E7: Assemble solutions and deliver to the customer. | F7: Develop, keep updated, and follow an integration strategy. | G7: Develop, keep updated, and use the integration environment. | H7: Develop, keep updated, and follow procedures and criteria for integrating solutions and components. | I7: Confirm, prior to integration, that each component has been properly identified and operates according to its requirements and design. | J7: Evaluate integrated components to ensure conformance to the solution's requirements and design. | K7: Integrate solutions and components according to the integration strategy. | L7: Review and keep updated interface or connection descriptions for coverage, completeness, and consistency throughout the solution's life. | M7: Confirm, prior to integration, that component interfaces or connections comply with interface or connection descriptions. | N7: Evaluate integrated components for interface or connection compatibility.
A8: Example Work Products | E8: assembled solutions and related documentation; | F8: product integration strategy (includes detail of content); recorded rationale for selection; selected integration strategy; | G8: verified and validated environment; build, buy or re-use analyses; support documentation for the environment; | H8: product integration procedures; product integration criteria; | I8: acceptance documents or test criteria for each product component; exception reports; | J8: integration evaluation reports; interface or connection evaluation reports; test reports; exception reports; | K8: integrated solution or components; exception or test report | L8: interface or connection review results; list of action items for updating interfaces or connections; updated interface or connection descriptions; | M8: results of comparison to description of component interfaces or connections; list of non-compliances; list of action items for updating descriptions; updated descriptions | N8: Interface or connection issues report;
A9: Example Activities | E9: assemble solution; record all necessary information to install and use; use applicable methods to package and deliver; deliver solution and related doc.; | F9: identify and record product components to be integrated; identify how solutions and components will be verified and validated; identify alternative integration strategies; select best alternative; periodically review strategy and revise; record and communicate decision rationale and status; | G9: develop requirements for the integration environment; develop verification and validation procedures and criteria; decide whether to build, buy or re-use the environment; develop or acquire an integration environment; verify and validate the environment; use the environment; revise as needed; communicate with stakeholders; | H9: develop, use and update procedures for integration of product components; develop, use and update criteria for integration and evaluation; record, update and communicate product integration procedures and criteria; | I9: track the integration readiness status of the components; ensure components are delivered as described in strategy and procedures; confirm each component is correctly identified and received; verify and validate each received component meets its requirements and design; check the status of the current configuration against expected; check all physical interfaces before integration; communicate results with stakeholders; | J9: evaluate integrated components, interfaces and testing using the integration strategy, procedures and criteria; record and communicate evaluation results; | K9: confirm readiness of the product integration environment; integrate components according to the strategy, procedures and criteria; update the product integration strategy, procedures and criteria as needed; integrate and deliver the product and communicate results; | L9: review with stakeholders and update interface or connection descriptions for coverage, completeness, and consistency; resolve interface or connection issues; update interface or connection descriptions and make accessible; | M9: compare interface or connection descriptions with component interfaces or connections and identify non-compliances; address non-compliances and communicate results | N9: Evaluate integrated components for compatibility; record and communicate the evaluation results;
A10: Standard Questions - explain how / what ? ... | F10: - Describe your integration strategy and how it is updated. | G10: - Describe your integration environment and how it is updated or maintained. | H10: - Describe the procedures and criteria you use to integrate components and solutions? | I10: - How do you ensure, prior to integration, that each component has been properly identified and operates according to its requirements and design? | J10: - How do you evaluate integrated components to ensure conformance to the solution's requirements and design? | K10: - Describe the integration of the components - how you follow the strategy? | L10: - How do you review and keep updated interface or connection descriptions for coverage, completeness, and consistency throughout the solution's life? | M10: - How do you confirm, prior to integration, that component interfaces or connections comply with interface or connection descriptions? | N10: - How do you evaluate integrated components for interface or connection compatibility?
A11: Questions | F11: 描述集成策略 | G11: 描述集成环境 | H11: 描述用于集成组件和解决方案的规程和准则 | I11: 在集成之前，如何确认每个组件已被正确识别、并按照其需求和设计正常工作？ | J11: 如何评价已集成的组件以确保其符合解决方案的需求和设计？ | K11: 描述下您是如何按照集成策略来集成组件的。 | L11: 在整个解决方案的生命周期中，如何评审并持续更新接口或连接描述的覆盖范围、完整性和一致性？ | M11: 在集成之前，如何确认组件的接口是符合接口描述的？ | N11: 如何评价已集成组件的接口的兼容性？
A15: Name | B15: link | C15: engl | D15: \PAs | E15: PI 1.1 | F15: PI 2.1 | G15: PI 2.2 | H15: PI 2.3 | I15: PI 2.4 | J15: PI 2.5 | K15: PI 2.6 | L15: PI 3.1 | M15: PI 3.2 | N15: PI 3.3
A16: Product Integration Plan | B16: link | C16: =HYPERLINK("02-项目级\P2-Qcubic to MySQL数据同步工具 V1.0\01-生存周期\06-实现\02-产品集成\01-产品集成计划(QCUBIC-SJTB-PI-Plan)V1.0-engl.docx", "engl") -> engl | E16: x | F16: x | G16: x | H16: x
A17: Product Integration Phase Report | B17: link | C17: =HYPERLINK("02-项目级\P2-Qcubic to MySQL数据同步工具 V1.0\01-生存周期\06-实现\02-产品集成\06-产品集成阶段报告\03-产品集成阶段报告(QCUBIC-SJTB-PI-InterimReport-3)V1.0-engl.docx", "engl") -> engl | E17: x | H17: x | J17: x | K17: x | N17: x
A18: atm to complete | B18: link | C18: =HYPERLINK("01-组织级\01-组织财富库\01-标准过程文件库\02-软件工程规范\04-实现\实现过程文件 (QCUBIC-SPI-DEV-Proc-Doc)V1.2-engl.docx", "engl") -> engl | H18: x
A19: atm to complete | B19: link | C19: =HYPERLINK("01-组织级\01-组织财富库\01-标准过程文件库\02-软件工程规范\05-测试\02-产品集成及集成测试\产品集成指南(QCUBIC-SPI-VV-Guid-PI)V1.2-engl.docx", "engl") -> engl | H19: x
A20: atm to complete | B20: link | C20: =HYPERLINK("02-项目级\P2-Qcubic to MySQL数据同步工具 V1.0\01-生存周期\06-实现\02-产品集成\03-产品集成检查列表(QCUBIC-SJTB-PI-PIChkList)V1.0-engl.xlsx", "engl") -> engl | I20: x
A21: atm to complete | B21: link | C21: =HYPERLINK("02-项目级\P2-Qcubic to MySQL数据同步工具 V1.0\01-生存周期\07-测试\02-集成测试\01-集成测试用例(QCUBIC-SJTB-VV-TestCase-SystemTest)V1.0-engl.xlsx", "engl") -> engl | J21: x
A22: atm to complete | B22: link | C22: =HYPERLINK("02-项目级\P2-Qcubic to MySQL数据同步工具 V1.0\01-生存周期\07-测试\02-集成测试\04-集成测试报告(QCUBIC-SJTB-LP_VV_IntegrationTestRet)V1.0-engl.docx", "engl") -> engl | J22: x
A23: atm to complete | B23: link | C23: =HYPERLINK("02-项目级\P2-Qcubic to MySQL数据同步工具 V1.0\01-生存周期\05-设计\01-概要设计书(QCUBIC-SJTB-TS-BD)V1.0-engl.docx", "engl") -> engl | L23: x | M23: x
A24: atm to complete | B24: link | C24: =HYPERLINK("02-项目级\P2-Qcubic to MySQL数据同步工具 V1.0\01-生存周期\05-设计\03-详细设计说明书(QCUBIC-SJTB-TS-DD)V1.0-engl.docx", "engl") -> engl | L24: x | M24: x
A25: atm to complete | B25: link | C25: =HYPERLINK("02-项目级\P2-Qcubic to MySQL数据同步工具 V1.0\01-生存周期\06-实现\02-产品集成\04-接口检查列表(QCUBIC-SJTB-PI-PIChkList)V1.0-engl.xlsx", "engl") -> engl | L25: x | M25: x | N25: x
A26: atm to complete | B26: link | C26: =HYPERLINK("02-项目级\P2-Qcubic to MySQL数据同步工具 V1.0\01-生存周期\06-实现\03-代码检查\02-代码调试BUG管理表(QCUBIC-SJTB-VV-CDBugList)V1.0-engl.xlsx", "engl") -> engl | L26: x | M26: x

Sheet TV_PR
A1: PR -PEER REVIEWS (PR)
A2: Intent | E2: Identify and address work product issues through reviews by the producer's peers or Subject Matter Experts (SMEs).
A3: Value | E3: Reduce cost and rework by uncovering issues or defects early.
E4: Level 1 | F4: Level 2 | J4: Level 3
E5: some measurement in place | F5: achieve full intent; use local measures to analyse performance / data stored / actions taken | J5: use organisational standards and tailoring; contribute improvements; set performance objectives; proactive not reactive
E6: PR 1.1 | F6: PR 2.1 | G6: PR 2.2 | H6: PR 2.3 | I6: PR 2.4 | J6: PR 3.1
A7: Practice | E7: Perform reviews of work products and record issues. | F7: Develop and keep updated procedures and supporting materials used to prepare for and perform peer reviews. | G7: Select work products to be peer reviewed. | H7: Prepare and perform peer reviews on selected work products using established procedures. | I7: Resolve issues identified in peer reviews. | J7: Analyze results and data from peer reviews.
A8: Example Work Products | E8: list of issues from work product reviews; | F8: procedures for preparing and performing peer reviews; supporting materials; | G8: work product selection criteria; list of selected work products; | H8: list of work products; schedule; peer review results; | I8: resolution of issues; results; | J8: analysis results;
A9: Example Activities | E9: review work products to identify issues; record results; | F9: record and update peer review procedures; record and update related supporting materials; | G9: evaluate the criticality of the work product; determine and record the review type to use; | H9: develop schedule; follow procedures; record results; communicate results to stakeholders; | I9: resolve issues; record resolutions and results and communicate to stakeholders; | J9: analyse the results of peer reviews; record and communicate analysis results; register improvements based on results; take corrective action on the project based on the results of the peer reviews; monitor the performance of processes for possible signals from peer review data;
A10: Standard Questions - explain how / what ? ... | F10: What procedures and supporting materials do you have in place to perform peer reviews? | G10: What work products have been selected to be reviewed? How do you select work products to be peer reviewed? | H10: Explain how you prepare for and perform peer reviews. | I10: Explain how you resolve the issues identified in the peer reviews. | J10: Explain how you analyse the results and what do you do with the analysed data from the peer reviews?
A11: Questions | F11: 准备和执行同行评审的步骤有哪些 | G11: 选择进行同行评审的工作产品有哪些？ | H11: 同行评审的既定程序（从准备阶段到结束）有哪些？请描述 | I11: 如何解决同行评审中发现的问题 | J11: 如何分析从同行评审得到的结果和数据
A15: Name | B15: link | C15: engl | D15: \PAs | E15: PR 1.1 | F15: PR 2.1 | G15: PR 2.2 | H15: PR 2.3 | I15: PR 2.4 | J15: PR 3.1
A16: atm to complete | B16: link | C16: =HYPERLINK("02-项目级\P3-主从数据库复制及性能提升项目\01-生存周期\03-项目策划\03-项目计划书 (QCUBIC-XNTS-PLAN-Plan)V1.1-engl.docx", "engl") -> engl | E16: x | H16: x
A17: atm to complete | B17: link | C17: =HYPERLINK("02-项目级\P3-主从数据库复制及性能提升项目\02-全程管理\05-评审管理\03-计划评审\05-评审报告_项目计划(QCUBIC-XNTS-PR-ReviewRpt)V1.1-engl.xlsx", "engl") -> engl | E17: x | F17: x | G17: x | H17: x | I17: x
A18: atm to complete | B18: link | C18: =HYPERLINK("02-项目级\P3-主从数据库复制及性能提升项目\02-全程管理\05-评审管理\04-需求评审\01-需求规格说明书\05-评审报告_需求规格说明书(QCUBIC-XNTS-PR-ReviewRpt)V1.1-engl.xlsx", "engl") -> engl | E18: x | G18: x | H18: x | I18: x
A19: atm to complete | B19: link | C19: =HYPERLINK("02-项目级\P3-主从数据库复制及性能提升项目\02-全程管理\05-评审管理\04-需求评审\02-用户需求说明书\03-评审报告_用户需求说明书(QCUBIC-XNTS-PR-ReviewRpt)V1.0-engl.xlsx", "engl") -> engl | E19: x | G19: x | H19: x | I19: x
A20: atm to complete | B20: link | C20: =HYPERLINK("02-项目级\P3-主从数据库复制及性能提升项目\02-全程管理\05-评审管理\05-设计评审\01-概要设计说明书\05-评审报告_概要设计书(QCUBIC-XNTS-PR-ReviewRpt)V1.1-engl.xlsx", "engl") -> engl | E20: x | G20: x | H20: x | I20: x
A21: atm to complete | B21: link | C21: =HYPERLINK("02-项目级\P3-主从数据库复制及性能提升项目\02-全程管理\05-评审管理\05-设计评审\02-详细设计说明书\05-评审报告_详细设计(QCUBIC-XNTS-PR-ReviewRpt)V1.1-engl.xlsx", "engl") -> engl | E21: x | G21: x | H21: x | I21: x
A22: atm to complete | B22: link | C22: =HYPERLINK("02-项目级\P3-主从数据库复制及性能提升项目\02-全程管理\05-评审管理\07-测试评审\02-系统测试用例\05-评审报告_系统测试用例(QCUBIC-XNTS-PR-ReviewRpt)V1.1-engl.xlsx", "engl") -> engl | E22: x | G22: x | H22: x | I22: x | J22: x
A23: atm to complete | B23: link | C23: =HYPERLINK("02-项目级\P3-主从数据库复制及性能提升项目\02-全程管理\05-评审管理\03-计划评审\01-评审准备表_项目计划(QCUBIC-XNTS-PR-ReviewPrp)V1.0-engl.docx", "engl") -> engl | F23: x
A24: atm to complete | B24: link | C24: =HYPERLINK("02-项目级\P3-主从数据库复制及性能提升项目\02-全程管理\05-评审管理\03-计划评审\02-评审检查表_项目计划(QCUBIC-XNTS-PR-RevChkList)V1.0-engl.xlsx", "engl") -> engl | F24: x
A25: atm to complete | B25: link | C25: =HYPERLINK("01-组织级\01-组织财富库\01-标准过程文件库\03-支持类\05-评审管理\评审管理过程文件(QCUBIC-SPI-VV-Proc-Doc)V1.2-engl.docx", "engl") -> engl | F25: x | H25: x
A26: atm to complete | B26: link | C26: =HYPERLINK("01-组织级\01-组织财富库\01-标准过程文件库\03-支持类\05-评审管理\评审指南(QCUBIC-SPI-VV-Guid-Review)V1.2-engl.docx", "engl") -> engl | F26: x
A27: atm to complete | B27: link | C27: =HYPERLINK("02-项目级\P3-主从数据库复制及性能提升项目\02-全程管理\05-评审管理\01-评审缺陷管理表(QCUBIC-XNTS-MC-DefectList)V1.0-engl.xlsx", "engl") -> engl | I27: x | J27: x

Sheet TV_VV
A1: VV -VERIFICATION AND VALIDATION (VV)
A2: Intent | E2: Verification and validation includes activities that: Confirm selected solutions and components meet their requirements Validate selected solutions and components fulfill their intended use in their target environment
A3: Value | E3: Verification and validation of selected solutions and components throughout the project increases the likelihood that the solution will satisfy the customer.
E4: Level 1 | G4: Level 2 | J4: Level 3
E5: some measurement in place | G5: achieve full intent; use local measures to analyse performance / data stored / actions taken | J5: use organisational standards and tailoring; contribute improvements; set performance objectives; proactive not reactive
E6: VV 1.1 | F6: VV 1.2 | G6: VV 2.1 | H6: VV 2.2 | I6: VV 2.3 | J6: VV 3.1 | K6: VV 3.2
A7: Practice | E7: Perform verification to ensure the requirements are implemented and record and communicate results. | F7: Perform validation to ensure the solution will function as intended in its target environment and record and communicate results. | G7: Select components and methods for verification and validation. | H7: Develop, keep updated, and use the environment needed to support verification and validation. | I7: Develop, keep updated, and follow procedures for verification and validation. | J7: Develop, keep updated, and use criteria for verification and validation. | K7: Analyze and communicate verification and validation results.
A8: Example Work Products | E8: verfication results; action items; | F8: validation results; analysis results; | G8: list of solution components for verification and validation; verfification and validation methods for each component; list of requirements to be verified and validated; | H8: verification environment; validation environment; | I8: verification procedures; validation procedures; verification and validation results; | J8: verification criteria; validation criteria; | K8: results of actual vs expected (test results); analysis results; corrective actions; improvement proposals;
A9: Example Activities | E9: perform verification of selected work products and solns, against requirements; record and communicate results of activities; identify action items resulting from verification; | F9: validate selected work products and solns. with stakeholders throughout life cycle to ensure they function as intended; analyse and communicate results of validation activities; | G9: select solution components for verification and validation; identify requirements to be satisfied by each; determine customer requirements and end user needs to be validated; define, record and update verification and validation methods; review validation selection, roles, responsibilities, constraints and methods with stakeholders; | H9: identify requirements for the verfification and validation environment; identify customer-supplied solutions and components; identify verification and validation resources, equipment and tools; develop or acquire and keep the verification and validation environments updated; | I9: identify criteria for selecting work products and activities for verification and validation; develop and keep updated procedures for verification and validation; perform verification and validation in accordance with procedures; | J9: develop verification and validation criteria and refine them as work progresses; | K9: compare actual to expected results; identify results that do not meet criteria for verification; identify results that do not meet criteria for validation; analyse results; submit improvement proposals where process improvements are identified; record and communicate analysis results and corrective actions to stakeholders;
A10: Standard Questions - explain how / what ? ... | G10: Explain how you select the components and the methods for verification and validation. | H10: Explain how you develop and maintain the environment needed to support verification and validation. | I10: How do you develop and maintain the procedures for verification and validation. | J10: How do you develop and maintain the criteria for verification and validation? | K10: How do you analyse and communicate the results of verification and validation?
A11: Questions | G11: 如何选择用于验证和确认的组件和方法？ | H11: 如何开发、使用并保持更新支持验证和确认所需的环境？ | I11: 这些(验证和确认的流程）是如何开发和维护的？ | J11: 这些（验证与确认的准则）是如何开发和维护的？ | K11: 如何使用和传达验证与确认的结果？
A15: Name | B15: link | C15: engl | D15: \PAs | E15: VV 1.1 | F15: VV 1.2 | G15: VV 2.1 | H15: VV 2.2 | I15: VV 2.3 | J15: VV 3.1 | K15: VV 3.2
A16: atm to complete | B16: link | C16: =HYPERLINK("02-项目级\P3-主从数据库复制及性能提升项目\01-生存周期\07-测试\01-测试计划(QCUBIC-XNTS-VV-TestPlan)V1.0-engl.docx", "engl") -> engl | E16: x | F16: x | G16: x | H16: x | I16: x | J16: x | K16: x
A17: atm to complete | B17: link | C17: =HYPERLINK("02-项目级\P3-主从数据库复制及性能提升项目\01-生存周期\07-测试\03-系统测试\03-系统测试BUG管理表(QCUBIC-XNTS-VV-STBugList)V1.0-engl.xlsx", "engl") -> engl | E17: x | F17: x | G17: x | H17: x
A18: atm to complete | B18: link | C18: =HYPERLINK("02-项目级\P3-主从数据库复制及性能提升项目\01-生存周期\07-测试\03-系统测试\04-系统测试报告(QCUBIC-XNTS-VV-TestReport-SystemTest)V1.0-engl.docx", "engl") -> engl | E18: x | G18: x | H18: x | I18: x | K18: x
A19: atm to complete | B19: link | C19: =HYPERLINK("02-项目级\P3-主从数据库复制及性能提升项目\01-生存周期\07-测试\02-集成测试\04-集成测试报告(QCUBIC-XNTS-LP_VV_IntegrationTestRet)V1.0-engl.docx", "engl") -> engl | E19: x | G19: x | H19: x | I19: x | K19: x
A20: atm to complete | B20: link | C20: =HYPERLINK("02-项目级\P3-主从数据库复制及性能提升项目\01-生存周期\08-试运行及验收\02-验收\01-验收计划(QCUBIC-XNTS-DA-AcceptencePlan)V1.0-engl.docx", "engl") -> engl | F20: x | I20: x | J20: x
A21: atm to complete | B21: link | C21: =HYPERLINK("02-项目级\P3-主从数据库复制及性能提升项目\01-生存周期\08-试运行及验收\02-验收\03-验收报告(QCUBIC-XNTS-VV-TestReport-AcceptenceReport)V1.0-engl.docx", "engl") -> engl | F21: x | I21: x | K21: x
A22: atm to complete | B22: link | C22: =HYPERLINK("01-组织级\01-组织财富库\01-标准过程文件库\02-软件工程规范\05-测试\测试用例规范(QCUBIC-SPI-VV-Tem-STD-TestExampleStd)V1.2-engl.docx", "engl") -> engl | I22: x
A23: atm to complete | B23: link | C23: =HYPERLINK("01-组织级\01-组织财富库\01-标准过程文件库\02-软件工程规范\06-试运行及验收\试运行及验收过程文件(QCUBIC-SPI-DA-Proc-Doc)V1.2-engl.docx", "engl") -> engl | I23: x
A24: atm to complete | B24: link | C24: =HYPERLINK("01-组织级\01-组织财富库\01-标准过程文件库\02-软件工程规范\05-测试\软件测试过程文件(QCUBIC-SPI-Tes-Proc-Doc)V1.2-engl.docx", "engl") -> engl | I24: x

Sheet TV_PQA
A1: PQA - PROCESS QUALITY ASSURANCE (PQA)
A2: Intent | E2: Verify and enable improvement of the quality of the performed processes and resulting work products.
A3: Value | E3: Increases the consistent use and improvement of the processes to maximize business benefit and customer satisfaction.
E4: Level 1 | F4: Level 2 | J4: Level 3
E5: some measurement in place | F5: achieve full intent; use local measures to analyse performance / data stored / actions taken | J5: use organisational standards and tailoring; contribute improvements; set performance objectives; proactive not reactive
E6: PQA 1.1 | F6: PQA 2.1 | G6: PQA 2.2 | H6: PQA 2.3 | I6: PQA 2.4 | J6: PQA 3.1
A7: Practice | E7: Identify and address process and work product issues. | F7: Develop, keep updated, and follow a quality assurance approach and plan based on historical quality data. | G7: Throughout the project, objectively evaluate selected performed processes and work products against the recorded process and applicable standards. | H7: Communicate quality and non-compliance issues and ensure their resolution. | I7: Record and use results of quality assurance activities. | J7: Identify and record opportunities for improvement during quality assurance activities.
A8: Example Work Products | E8: recorded issues; addressed issues; | F8: Quality assurance approach and plan; | G8: criteria; checklists; evaluation reports; non-compliance reports; improvement proposals; | H8: quality trend analysis reports; non-compliance resolutions; | I8: evaluation records; quality assurance reports; status reports of non-compliance issues and corrective actions; reports of quality trends; | J8: improvement proposals;
A9: Example Activities | E9: identify issues; record issues; resolve issues; | F9: develop, record and update the quality approach and plan; identify areas for evaluation; review, update and approve approach with stakeholders; | G9: develop and update clearly stated criteria for evaluations; develop and update checklists based on process descriptions; use the defined criteria and checklists to evaluate if performed processes follow process descriptions; identify and record non-compliances; leverage recorded best practices; | H9: communicate and resolve each non-compliance issue; escalate non-compliance issues that cannot be resolved; analyse to identify trends; ensure stakeholders are aware of evaluation results; | I9: record and update information about quality assurance activities; | J9: record potential improvements observed during QA activities; submit improvement proposals;
A10: Standard Questions - explain how / what ? ... | E10: *How do you identify which work products and processes you want to check for process quality assurance? | F10: *How do you develop the approach or plan for quality assurance? *What historical data do you use? | G10: *How do you evaluate compliance to the recorded processes and work products? *What do you check for? | H10: * How do you communicate and address the non-compliance issues that have been identified? | I10: *Where do you record the results of quality assurance activities? *How do you use the results? What actions follow? *Where does your function report to? *Repeat offenders? *Who has accountability for taking action on results? *Most common areas of non-compliance? | J10: *What do you do with the improvement opportunities that you identify? *Do you follow-up on the use of these opportunities identified? *Effect of non-compliance on process performance baseline? Used by MA?
A11: Questions | F11: 你是如何指定QA方法或计划的？使用到了哪些历史数据？ | G11: “*您如何评估所记录过程和工作产品的合规性? 你检查什么? | H11: “*对于已发现的不符合项问题，你们如何沟通和解决的?” | I11: *你们在哪里记录QA活动的结果? 你如何使用这些结果?遵循什么行动? *你的职能部门向哪里报告? *常出现的不符合项? 谁有责任根据结果采取行动? *最常见的违规行为? | J11: “*当你发现有改进的机会时，你会怎么做?” *你会继续利用这些发现的机会吗? *不合规对过程性能基线的影响?度量分析人员会使用这些（改进机会）嘛?
A15: Name | B15: link | C15: engl | D15: \PAs | E15: PQA 1.1 | F15: PQA 2.1 | G15: PQA 2.2 | H15: PQA 2.3 | I15: PQA 2.4 | J15: PQA 3.1
A16: atm to complete | B16: link | C16: =HYPERLINK("01-组织级\02-组织工作库\03-PQA活动库\组织级的质量保证计划(QCUBIC-SPI-PQA-OQAPlan)V1.4-engl.xlsx", "engl") -> engl | E16: x | F16: x | G16: x | H16: x | I16: x | J16: x
A17: atm to complete | B17: link | C17: =HYPERLINK("01-组织级\02-组织工作库\03-PQA活动库\组织级不符合项管理表(QCUBIC-SPI-PQA-NCList)V1.2-engl.xlsx", "engl") -> engl | E17: x | F17: x | H17: x | I17: x
A18: atm to complete | B18: link | C18: =HYPERLINK("01-组织级\02-组织工作库\03-PQA活动库\组织级工作产品和过程检查表(QCUBIC-ORG-PQA-Checklist_20200627)V1.0-engl.xlsx", "engl") -> engl | G18: x
A19: atm to complete | B19: link | C19: =HYPERLINK("01-组织级\02-组织工作库\03-PQA活动库\组织质量保证报告\质量保证报告(QCUBIC-SPI-PQA-Report_20200627)V1.0-engl.xlsx", "engl") -> engl | I19: x
A20: atm to complete | B20: link | C20: =HYPERLINK("01-组织级\02-组织工作库\02-EPG活动库\07-EPG跟踪\05-过程改进建议表\过程改进建议表(QCUBIC-SPI-PIM-SPIAdvic)V1.2-engl.xlsx", "engl") -> engl | J20: x

Sheet TV_RDM
A1: RDM - REQUIREMENTS DEVELOPMENT AND MANAGEMENT (RDM)
A2: Intent | E2: Elicit requirements, ensure common understanding by stakeholders, and align requirements, plans, and work products.
A3: Value | E3: Ensures that customer's needs and expectations are satisfied.
E4: Level 1 | F4: Level 2 | L4: Level 3
E5: some measurement in place | F5: achieve full intent; use local measures to analyse performance / data stored / actions taken | L5: use organisational standards and tailoring; contribute improvements; set performance objectives; proactive not reactive
E6: RDM 1.1 | F6: RDM 2.1 | G6: RDM 2.2 | H6: RDM 2.3 | I6: RDM 2.4 | J6: RDM 2.5 | K6: RDM 2.6 | L6: RDM 3.1 | M6: RDM 3.2 | N6: RDM 3.3 | O6: RDM 3.4 | P6: RDM 3.5 | Q6: RDM 3.6 | R6: RDM 3.7
A7: Practice | E7: Record requirements. | F7: Elicit stakeholder needs, expectations, constraints, and interfaces or connections. | G7: Transform stakeholder needs, expectations, constraints, and interfaces or connections into prioritized customer requirements. | H7: Develop an understanding with the requirements providers on the meaning of the requirements. | I7: Obtain commitment from project participants that they can implement the requirements. | J7: Develop, record, and maintain bidirectional traceability among requirements and activities or work products. | K7: Ensure that plans and activities or work products remain consistent with requirements. | L7: Develop and keep requirements updated for the solution and its components. | M7: Develop operational concepts and scenarios. | N7: Allocate the requirements to be implemented. | O7: Identify, develop, and keep updated interface or connection requirements. | P7: Ensure that requirements are necessary and sufficient. | Q7: Balance stakeholder needs and constraints | R7: Validate requirements to ensure the resulting solution will perform as intended in the target environment.
A8: Example Work Products | E8: list of requirements; statement of work; use cases; | F8: list of stakeholder needs, constraints, expectations; list of interfaces or connections; | G8: prioritised customer requirements; customer constraints; | H8: list of appropriate requirements providers; criteria for evaluation and acceptance of requirements; results of analyses against criteria; - Recorded changes to requirements - Set of approved requirements | I8: impact assessment; recorded commitments that requirements can be met; | J8: records of bidirectional requirements traceability; | K8: records of inconsistencies between requirements, plans and work products; | L8: requirements; | M8: operational concepts and scenarios; | N8: requirement allocations; | O8: interface or connection requirements; interface or connection requirements review results; action items for updating interface or connection requirements; - Updated interface or connection requirements | P8: requirements analysis results; | Q8: analysis results; proposed requirements changes; | R8: selected validation techniques; record of validation results; updated requirements;
A9: Example Activities | E9: record the requirements; | F9: demonstrations, interviews, questionnaires, scenarios, surveys, brainstorming, beta testing, use cases, business cases | G9: document customer requirements; develop a prioritisation of customer requirements; | H9: develop criteria for identifying providers; develop criteria for evaluation and acceptance of req.; analyse req. to ensure criteria are met; obtain commitments from providers and participants; record changes; | I9: assess impact on existing commitments; negotiate and record commitments; | J9: Develop, record, and maintain bidirectional traceability; | K9: review plans, activities for consistency with requirements; record inconsistencies and sources; initiate and record any corrective actions and communicate to stakeholders; | L9: develop, record, and update requirements in technical terms for solution selections and component design; record bidirectional traceability; review for impoact to architecture and design; record prioritisation; record nontechnical req.; identify and record req. for external interfaces and connections; | M9: develop operational concepts and scenarios; review and refine with stakeholders; | N9: allocate the requirements to be implemented; record and update relationships; review allocations and relationships; | O9: identify, record, update internal and external interface or connection requirements; review for coverage and completeness with stakeholders; | P9: perform a requirements analysis; review results and update; | Q9: analyse to ensure they balance; review and negotiate trade-offs; record and update changes with stakeholders; | R9: identify and select validation techniques; validate using techniques; review and communicate results; update requirements;
A10: Standard Questions - explain how / what ? ... | E10: - What requirements have you documented (or recorded) | F10: - (Explain) How do you elicit (extract) stakeholder needs, expectations, constraints, and interfaces (or connections)? | G10: - (Explain) How do you transform stakeholder needs, expectations, contains, and interfaces (or connections) into prioritized customer requirements? | H10: - (Explain) How do you developed and understanding with the requirements provider on the meaning of the requirements? | I10: - (Explain) How (or what) commitments do you obtain from project participants (developers, testers, etc) that they can implement the requirements? | J10: What bidirectional traceability do you develop and maintain among requirements, other work products or planned activities? | K10: How do you ensure that plans and activities (or work products to be delivered) are consistent with the requirements? | L10: How do you ensure that requirements are kept up to date for the solution (and its components)? | M10: - What operational concepts and scenarios do you develop for requirements? | N10: - How do you allocate requirements for implementation? | O10: - How do you identify, develop, and keep updated interfaces or connection requirements? | P10: - How do you ensure requirements are necessary and sufficient? | Q10: - How do you balance stakeholder needs and constraints? | R10: - How do you validate requirements to ensure the resulting solution will perform as intended in the target environment?
A11: Questions | F11: —(解释)您如何引出(获取)干系人的需求、期望、约束和接口(或连接)? | G11: —(解释)你如何将干系人的需求、期望、约束条件和接口(或连接)转换为优先级的客户需求? | H11: —(解释)你是如何开发需求并与需求提供者一起理解需求的含义的? | I11: —(解释)你如何(或什么)从项目参与者(开发人员、测试人员等)那里获得他们能够实现需求的承诺? | J11: 在需求、其他工作产品或计划的活动中，您开发并维护什么样的双向追溯性? | K11: 您如何确保计划和活动(或要交付的工作产品)与需求保持一致? | L11: 您如何确保解决方案(及其组件)的需求是最新的? | M11: ’—您针对需求开发了哪些操作概念和场景? | N11: —如何分配待实现的需求? | O11: —您如何识别、开发和更新接口或连接需求? | P11: —你如何确保需求是必要和充分的? | Q11: ——你如何平衡干系人的需求和约束条件? | R11: ’—您如何验证需求，以确保最终解决方案在目标环境中能够按照预期的方式执行?
A15: Name | B15: link | C15: engl | D15: \PAs | E15: RDM 1.1 | F15: RDM 2.1 | G15: RDM 2.2 | H15: RDM 2.3 | I15: RDM 2.4 | J15: RDM 2.5 | K15: RDM 2.6 | L15: RDM 3.1 | M15: RDM 3.2 | N15: RDM 3.3 | O15: RDM 3.4 | P15: RDM 3.5 | Q15: RDM 3.6 | R15: RDM 3.7
A16: atm to complete | B16: link | C16: =HYPERLINK("02-项目级\P3-主从数据库复制及性能提升项目\01-生存周期\04-需求\04-需求调研报告\01-需求调研报告(QCUBIC-XNTS-RDM-Report-20220113pm)V1.0-engl.docx", "engl") -> engl | E16: x | R16: x
A17: atm to complete | B17: link | C17: =HYPERLINK("02-项目级\P3-主从数据库复制及性能提升项目\01-生存周期\04-需求\02-需求规格说明书 (QCUBIC-XNTS-RDM-SRS)V1.1-engl.docx", "engl") -> engl | E17: x | F17: x | G17: x | H17: x | I17: x | J17: x | L17: x | M17: x | N17: x | O17: x | P17: x | Q17: x | R17: x
A18: atm to complete | B18: link | C18: =HYPERLINK("02-项目级\P3-主从数据库复制及性能提升项目\01-生存周期\04-需求\03-用户需求说明书(QCUBIC-XNTS-RDM-CRS)V1.1-engl.docx", "engl") -> engl | F18: x | G18: x | H18: x | I18: x
A19: atm to complete | B19: link | C19: =HYPERLINK("02-项目级\P3-主从数据库复制及性能提升项目\02-全程管理\05-评审管理\04-需求评审\01-需求规格说明书\05-评审报告_需求规格说明书(QCUBIC-XNTS-PR-ReviewRpt)V1.1-engl.xlsx", "engl") -> engl | H19: x | I19: x | P19: x | Q19: x | R19: x
A20: atm to complete | B20: link | C20: =HYPERLINK("02-项目级\P3-主从数据库复制及性能提升项目\02-全程管理\05-评审管理\04-需求评审\01-需求规格说明书\02-评审检查表_需求规格说明书(QCUBIC-XNTS-PR-Revchklist)V1.0-engl.xlsx", "engl") -> engl | I20: x | P20: x
A21: atm to complete | B21: link | C21: =HYPERLINK("02-项目级\P3-主从数据库复制及性能提升项目\01-生存周期\04-需求\05-需求跟踪矩阵\01-需求跟踪矩阵(QCUBIC-XNTS-RDM-RTX)V1.1-engl.xlsx", "engl") -> engl | J21: x | K21: x
A22: atm to complete | B22: link | C22: =HYPERLINK("02-项目级\P3-主从数据库复制及性能提升项目\01-生存周期\03-项目策划\03-项目计划书 (QCUBIC-XNTS-PLAN-Plan)V1.1-engl.docx", "engl") -> engl | K22: x
A23: atm to complete | B23: link | C23: =HYPERLINK("02-项目级\P3-主从数据库复制及性能提升项目\01-生存周期\04-需求\01-需求调研计划(QCUBIC-XNTS-RDM-Plan)V1.0-engl.docx", "engl") -> engl | K23: x
A24: atm to complete | B24: link | C24: =HYPERLINK("02-项目级\P3-主从数据库复制及性能提升项目\02-全程管理\06-变更管理\03-变更结果报告(QCUBIC-XNTS-mc-changereport_001)V1.0-engl.docx", "engl") -> engl | K24: x | L24: x
A25: atm to complete | B25: link | C25: =HYPERLINK("02-项目级\P3-主从数据库复制及性能提升项目\02-全程管理\06-变更管理\02-变更列表(QCUBIC-XNTS-MC-CRecoRDM)V1.0-engl.xlsx", "engl") -> engl | L25: x

Sheet TV_PCM
A1: PCM - PROCESS MANAGEMENT (PCM)
A2: Intent | E2: Manages and implements the continuous improvement of processes and infrastructure to: Support accomplishing business objectives Identify and implement the most beneficial process improvements Make the results of process improvement visible, accessible, and sustainable
A3: Value | E3: Ensures that processes, infrastructure, and their improvement contribute to successfully meeting business objectives.
E4: Level 1 | H4: Level 2 | J4: Level 3 | O4: Level 3 | P4: Level 4
E5: some measurement in place | H5: achieve full intent; use local measures to analyse performance / data stored / actions taken | J5: use organisational standards and tailoring; contribute improvements; set performance objectives; proactive not reactive | O5: use organisational standards and tailoring; contribute improvements; set performance objectives; proactive not reactive | P5: use measurement and analysis to control/ stabilise/ predict/ identify and reduce variance; set QPPOs to meet Bos
E6: PCM 1.1 | F6: PCM 1.2 | G6: PCM 1.3 | H6: PCM 2.1 | I6: PCM 2.2 | J6: PCM 3.1 | K6: PCM 3.2 | L6: PCM 3.3 | M6: PCM 3.4 | N6: PCM 3.5 | O6: PCM 3.6 | P6: PCM 4.1
A7: Practice | E7: Develop a support structure to provide process guidance, identify and fix process problems, and continuously improve processes. | F7: Appraise the current process implementation and identify strengths and weaknesses. | G7: Address improvement opportunities or process issues. | H7: Identify improvements to the processes and process assets. | I7: Develop, keep updated, and follow plans for implementing selected process improvements. | J7: Develop, keep updated, and use process improvement objectives traceable to the business objectives. | K7: Identify processes that are the largest contributors to meeting business objectives. | L7: Explore and evaluate potential new processes, techniques, methods, and tools to identify improvement opportunities. | M7: Provide support for implementing, deploying, and sustaining process improvements. | N7: Deploy organizational standard processes and process assets. | O7: Evaluate the effectiveness of deployed improvements in achieving process improvement objectives. | P7: Use statistical and other quantitative techniques to validate selected performance improvements against proposed improvement exceptions, business objectives, or quality and process performance objectives.
A8: Example Work Products | E8: process support structure - EPG; | F8: appraisal plan and schedule; appraisal findings; | G8: action items; | H8: proposed improvement list; recorded selection criteria; list of selected improvements for implementation; | I8: process improvement plan; action plan; developed process assets; status report; recorded results; | J8: process improvement objectives traced to business objectives; | K8: description of relationships between bus. obj., processes and process objs.and value; | L8: potential improvement opportunities; | M8: plan for deployment; implementation records; | N8: list of whether improvements will be deployed; deployment status report; | O8: process improvement evaluation report; | P8: validation plans; validation reports (may include PPBs)
A9: Example Activities | E9: identify and apply a structure for supporting process related activities; assign responsibilities for co-ordinating process related activities; | F9: obtain sponsorship and support for appraisal from snr mgt; define scope of appraisal; select or define the criteria and method for appraisal; plan and schedule; perform appraisal; record and communicate findings; | G9: assign relevant personnel to address improvement opportunities and issues; identify and record action items; address opportunities and issues and communicate results; | H9: identify issues and improvements; group and analyse proposed improvements; record and update criteria for selecting improvements; select proposed improvements for implementation; review selections with stakeholders; record proposed improvements and communicate results; | I9: select performance improvements to deploy; develop plan; ensure deployment is announced, well co-ordinated and supported; manage progress, review, update; develop or update process assets; pilot improvements; deploy improvements; analyse and communicate results; record improvements; | J9: identify and record improvement objectives; review with stakeholders; monitor and update improvement objectives; | K9: review current business model, objectives, and environment; review potential internal or external business changes; identify and record relationships between objectives and processes; estimate value of each process contribution; record, update, communicate results; | L9: identify, research, and record improvements; use established criteria to decide which docs and measures to include in PAL; analyse and evaluate potential process improvement opportunities; record, update and communicate results; | M9: identify mechanisms needed to support process implementation and deployment; ensure that implementation and deployment activities are planned and co-ordinated; align multiple improvement activities; obtain snr mgt commitment for visible support of deployment; provide a migration approach; review deployment results with stakeholders; provide records about success, issues, obstacles; | N9: ensure sufficient support for deployment; identify projects for deployment; co-ordinate deployment of improved processes; deply org. set of standard processes and assets to projects; monitor deployment; review results of objective evaluation; identify, record and trackimplementation issues; review results with stakeholders; | O9: analyse current improvement results against business, process, and performance objectives; record results and communicate to stakeholders; initiate and track corrective actions; | P9: plan the validation; review plans with stakeholders; perform each validationaccording to plan; use statistical or other quant. methods to analyse validation results; review, record and communicate results of validation analysis;
A10: Standard Questions - explain how / what ? ... | E10: What process support structure (for example an EPG) do you have in place? | F10: What appraisals do you do on your current processes? - What appraisals (CMMI, COBIT, ISO) have you done on your current processes? | G10: What process improvement are registered? - How do you collect improvements submitted internally within the organisation? | H10: How do you identify improvements in processes and process assets? - How do you select the proposed improvements? | I10: What process improvement actions are followed to implement identified improvements? | J10: Explain how you link your process improvements to business objectives? | K10: How do you prioritise your process improvements? | L10: How do you evaluate potential new improvements opportunities. Improvements include new processes, techniques, methods and tools? | M10: What support is provided for implementing and deploying new process improvements? | N10: How are organisational standard processes and process assets deployed? | O10: How do you evaluate the effectiveness of improvements towards achieving business objectives? How do you evaluate the non-statistically measured improvements (small improvements)? | P10: - How do you make use of statistical and other quantitative techniques to validate selected performance improvements against proposed improvement exceptions, business objectives, or quality and process performance objectives?
A11: Questions | F11: 你是如何评估你目前的工作流程的? -你对目前的流程做过哪些评估(CMMI, COBIT, ISO) ? | G11: 记录了哪些流程改进? -你如何收集组织内部提交的改进? | H11: 针对过程和过程资产确定了哪些改进? -你如何确定和选择建议的改进? | I11: 遵循什么过程改进行动（计划）来实施已确定的改进? | J11: 如何将过程改进与业务目标联系起来? | K11: 您如何确定过程改进的优先级? | L11: 你如何评估潜在的新的改进机会?改进包括对过程、技术、方法和工具的改进。 | M11: 为实现和部署新的过程改进提供了什么支持? | N11: 如何部署组织的标准过程和过程资产? | O11: 您如何评估（为实现业务目标而进行的）改进的有效性? 如何评估非统计度量的改进(小改进)? | P11: - How do you make use of statistical and other quantitative techniques to validate selected performance improvements against proposed improvement exceptions, business objectives, or quality and process performance objectives?
A15: Name | B15: link | C15: engl | D15: \PAs | E15: PCM 1.1 | F15: PCM 1.2 | G15: PCM 1.3 | H15: PCM 2.1 | I15: PCM 2.2 | J15: PCM 3.1 | K15: PCM 3.2 | L15: PCM 3.3 | M15: PCM 3.4 | N15: PCM 3.5 | O15: PCM 3.6 | P15: PCM 4.1 | Q15: PCM 4.1
A16: atm to complete | B16: link | C16: =HYPERLINK("01-组织级\02-组织工作库\02-EPG活动库\03-过程改进计划\过程改进计划(QCUBIC-SPI-PIM-PIPlan)V1.2-engl.docx", "engl") -> engl | E16: x | H16: x | I16: x | J16: x | K16: x
A17: atm to complete | B17: link | C17: =HYPERLINK("01-组织级\02-组织工作库\02-EPG活动库\02-现场诊断\北京快立方科技有限公司现场诊断报告-engl.pptx", "engl") -> engl | F17: x
A18: atm to complete | B18: link | C18: =HYPERLINK("01-组织级\02-组织工作库\02-EPG活动库\过程改进总结报告-engl.pptx", "engl") -> engl | F18: x | L18: x | N18: x | O18: x
A19: atm to complete | B19: link | C19: =HYPERLINK("01-组织级\02-组织工作库\02-EPG活动库\01-EPG章程\EPG章程(QCUBIC-SPI-PIM-Std-EPGRule)V1.2-engl.docx", "engl") -> engl | F19: x
A20: atm to complete | B20: link | C20: =HYPERLINK("01-组织级\02-组织工作库\02-EPG活动库\07-EPG跟踪\05-过程改进建议表\过程改进建议表(QCUBIC-SPI-PIM-SPIAdvic)V1.2-engl.xlsx", "engl") -> engl | G20: x | M20: x
A21: atm to complete | B21: link | K21: x
A22: atm to complete | B22: link | C22: =HYPERLINK("01-组织级\02-组织工作库\02-EPG活动库\03-过程改进计划\关键子过程选择(QCUBIC_PCM_Select subprocess)V1.0-engl.xlsx", "engl") -> engl | K22: x
A23: atm to complete | B23: link | C23: =HYPERLINK("01-组织级\02-组织工作库\02-EPG活动库\03-过程改进计划\过程改进计划评审报告(QCUBIC-SPI-VV-Tem-ReviewRpt)V1.2-engl.xlsx", "engl") -> engl | L23: x
A24: atm to complete | B24: link | M24: x
A25: atm to complete | B25: link | C25: =HYPERLINK("01-组织级\02-组织工作库\02-EPG活动库\05-项目试点\试点行动计划(QCUBIC-SPI-PIM-PilotPlan)V1.1-engl.docx", "engl") -> engl | M25: x
A26: atm to complete | B26: link | C26: =HYPERLINK("01-组织级\02-组织工作库\02-EPG活动库\07-EPG跟踪\06-过程改进里程碑\过程改进里程碑报告(ORG_PCM_Milestone_20220628)V1.0-engl.docx", "engl") -> engl | N26: x
A27: atm to complete | B27: link | C27: =HYPERLINK("01-组织级\02-组织工作库\02-EPG活动库\06-过程推广\过程部署计划(QCUBIC-SPI-PIM-PSPreadPlan)V1.2-engl.docx", "engl") -> engl | N27: x

Sheet TV_PAD
A1: PAD - PROCESS ASSET DEVELOPMENT (PAD)
A2: Intent | E2: Develop and keep updated the process assets necessary to perform the work.
A3: Value | E3: Provides a capability to understand and repeat successful performance.
E4: Level 1 | F4: Level 2 | I4: Level 3
E5: some measurement in place | F5: achieve full intent; use local measures to analyse performance / data stored / actions taken | I5: use organisational standards and tailoring; contribute improvements; set performance objectives; proactive not reactive
E6: PAD 1.1 | F6: PAD 2.1 | G6: PAD 2.2 | H6: PAD 2.3 | I6: PAD 3.1 | J6: PAD 3.2 | K6: PAD 3.3 | L6: PAD 3.4 | M6: PAD 3.5 | N6: PAD 3.6 | O6: PAD 3.7
A7: Practice | E7: Develop process assets to perform the work. | F7: Determine what process assets will be needed to perform the work. | G7: Develop, buy, or reuse process assets. | H7: Make processes and assets available. | I7: Develop, keep updated, and follow a strategy for building and updating process assets. | J7: Develop, record, and keep updated a process architecture that describes the structure of the organization's processes and process assets. | K7: Develop, keep updated, and make processes and assets available for use. | L7: Develop, keep updated, and use tailoring criteria and guidelines for the set of standard processes and assets. | M7: Develop, keep updated, and make the organization's process asset library available for use. | N7: Develop, keep updated, and make work environment standards available for use. | O7: Develop, keep updated, and make organizational measurement and analysis standards available for use.
A8: Example Work Products | E8: work instructions; process descriptions; templates; | F8: templates; work instructions; tools; | G8: build, buy, re-use analysis results; process assets; | H8: process assets; | I8: strategy for building and updating process assets; | J8: process requirements; process architecture format; process architecture; | K8: action plans; status and results of action plans; org. set of standard processes and assets; new processes or assets; | L8: tailoring guidelines; waivers or requests for process waivers; | M8: design of org. PAL; org. PAL; process related work products in PAL; | N8: work env. standards; waivers or requests for work env. waivers; | O8: org. measuremnt and analysis standards; waivers or requests for measurement and analysis waivers;
A9: Example Activities | E9: record work instructions; | F9: identify process assets needed (for the project); | G9: select which assets will be analysed for build, buy, re-use; perform build, buy, re-use analysis; record results; build, buy or re-use the assets; | H9: make assets available for use (by projects); communicate availability of assets for use; | I9: develop a strategy for building and updating process assets; | J9: identify process requirements; identify process architecture objectives; develop and record format; develop, record, update process architecture; review and update with stakeholders; communicate and make available; | K9: verify that org. standard process set is aligned to strategic process needs and objectives; assign responsibilities for acquiring, developing, maintaining processes; review and decide if improvement recommendations should be incorporated; record process action plans; develop org. standards for processes and assets; track progress and commitments; establish process action teams; build and record processesand assets; perform reviews on standard processes and assets; revise processes and assets; make processes and assets available; | L9: specify selection criteria and procedures for tailoring; specify standards for recording defined process; specifu proceudres to submit and approve waivers from org std processes; record, approve, communicate tailoring guidelines; revise tailoring guidelines; | M9: design and implement the org. PAL; specify criteria for including assets in PAL; specify procedures for storing and retrieving assets; make assets available; periodically review usefulness of assets; enter selected assets in library; | N9: evaluate commercially available work environment standards; periodically analyse work env. to identify changes or resources that could improve; prioritise potential improvements to work env.; identify resources that could improve performance; ensure projects have authority to organise or tailor work env.; review work env. with project; adopt, develop or tailor work env. Stds. To fill gaps; | O9: specify org. standards for measurement and analysis; specify tailoring guidelines for applying measurement standards;
