Workbook

Sheet Read Me
A1: The intent of this workbook is to accelerate the capture of appraisal information necessary to generate the RGS.
A3: The [CAS] worksheet provides nearly all the Benchmark Phase 1 data entry fields in CAS through RGS generation. However, the [CAS] worksheet allows the lead appraiser to filter the data entry fields to focus on only those necessary for RGS generation. The CAS Kit, as distributed, has the filter set to only display the critical path fields on the [CAS] worksheet, and has hidden the columns of the non-critical path fields on the other worksheets as well.
A5: Filtering is applied by the filter code in Column A as follows: 1: Required to be provided prior to generating the RGS; 2: Required to be provided, but not until after the RGS has been generated; 3: Optional information which need not be input into CAS at all; MM: Data fields required for multiple model appraisals (the CAS Kit still needs to be enhanced for multiple model appraisals).
A7: The fields in the workbook are named as they are in CAS, and are provided in the same order, as those in CAS. I might suggest that the lead appraiser populate as much of the [CAS] worksheet information as possible prior to sending it to the Site Coordinator to get the balance of the critical path information.
A9: Some of the CAS-exportable Excel worksheets have been included. Note that the CMMI Institute can change the CAS downloadable worksheets at any time, but the informational content of critical path information is unlikely to be as volatile. This workbook will be kept as up-to-date as possible. Note that the tabs in this workbook are a bit more "user friendly" than those in the CAS-downloaded worksheets, but that means you cannot import CAS Kit worksheets directly into CAS. When using the CAS Kit, information from the worksheets is input into CAS by: 1. Download the "official" Excel workbooks from CAS; 2. Cut and paste data from the CAS Kit worksheet into the CAS downloaded workbook; 3. Import the populated CAS downloaded workbook back into CAS.
A11: The prefix for the names of the spreadsheet in this CAS Kit workbook are: - "T#" - "T" for "CAS Template" and the # indicates the iteration number of the CAS template. E.g., T3 is the 3rd CAS downloadable template (the first two deal with ATM training and experience - non-critical path data elements). - "X" - indicates a useful template that is not downloaded from (or uploadable to) CAS.
A13: The "X" worksheets include: 1. X-CLs - used to indicate the Capability Levels to be evaluated for non-benchmark views 2. X-Sampling Factors - used to gather initial information on Sampling Factors and Sampling Factor Values 3. X-Support Function Exceptions - used to indicate which PAs apply for each Support Function 4. X-Project Exceptions - used to indicate which PAs do not apply for each project. 5. X-Appraisal Team - used to capture ATM data that can be imported through 2 CAS downloadable spreadsheets.
A15: Useful Information related to some of the worksheets included in this "CAS Kit" workbook is provided below.
A18: T3-Support Functions
A19: 1. Fields required to generate RGS
A20: B. Function Name
A21: D. Size (FTEs)
... A108: Finally, any PA that is changed from "In-Scope" for a Project should be accompanied by an explanation as to why that PA is not in scope.. A column has been provided to document that explanation. Some examples, which are still likely to result in Quality Flags during the pre-RGS generation Quality Review, are: 1. "This early-in-the-lifecycle project has not yet had the need or opportunity to conduct a formal decision-making process." 2. "The project is in the requirements elicitation phase and has not yet performed any VV-related activities." 3. "For this project, RDM is deemed Out-of-Scope as the customer has contracted with a 3rd party to generated the Requirements Specification and to process all requirement changes."

Sheet CAS
A2: 1 | B2: Filter code for Column A | F2: 1: Required to be provided prior to generating the RGS
A3: 2 | F3: 2: Required to be provided, but not until after the RGS has been generated
A4: 3 | F4: 3: Optional information which need not be input into CAS at all
A5: MM | F5: MM: Data fields required for multiple model appraisals
A6: 1 | B6: CAS Section
A7: 1 | C7: Subsection
A8: 1 | D8: Entry Field Section
A9: 1 | E9: CAS Entry Field
A10: 1 | F10: Entry Fields | G10: Notes
A11: 1 | B11: New Appraisal
A12: 1 | E12: Appraisal Type | F12: Benchmark
A13: 1
A14: 1 | B14: New Benchmark Appraisal | G14: Note that this will hereafter be displayed as "Appraisal Setup" / "Appraisal Name and Type"
A15: 1 | E15: Appraisal Name | F15: CAS Kit Example #2 Multiple Model Benchmark Appraisal
A16: 1 | E16: Time Zone | F16: India time zone | G16: <Pull down menu in CAS>
A17: 1 | E17: Partner | F17: PACT | G17: <Pull down menu in CAS>
A18: 1 | E18: Business and Appraisal Objectives | F18: TBD
A19: 2 | E19: ATM Signature Required | G19: <Yes/No>, defaults to No
A20: 2 | E20: Appraisal Virtually Delivered | G20: <Yes/No>, defaults to No
A21: 2 | E21: 1. Entire appraisal virtual? | G21: <Yes/No>, defaults to No
A22: 3 | E22: 2. Any part of the appraisal virtual? | G22: <Yes/No>, defaults to No
A23: 2 | E23: 3. Virtual Technique Description | G23: MDD Phase 1, MDD 2.1 (Collect and Examine OE), MDD 3.1 (Deliver Appraisal Results), MDD 4.1.1, MDD 4.1.2
A24: 1 | B24: [Click "Add Appraisal"]
A25: 1
A26: 1 | B26: Organization
A27: 1 | C27: Organizational Info
A28: 1 | D28: New Organization
A29: 1 | E29: Name | F29: ACME Software Inc. | G29: Enter legal name of company being appraised.
A30: 3 | E30: Native Language Name | G30: Legal name of the organization in native language. If native language is English, leave blank.
A31: 3 | E31: Address Line 1 | G31: Street address, PO Box, Company name c/o (care/of)
A32: 3 | E32: Address Line 2 | G32: Apartment, suite, unit, building, floor, etc.
A33: 3 | E33: City
A34: 3 | E34: State/Province/Region
A35: 3 | E35: Zip/Postal Code
A36: 3 | E36: Country | G36: <Pull down menu in CAS>
A37: 3 | E37: Website Address/URL
A38: 3 | E38: Rationale for Projects Excluded from OU
A39: 3 | E39: ISIC Section - Division | G39: <Pull down menu in CAS>
A40: 1 | D40: [Click "Add Organization"]
A41: 1
...

Sheet X-CLs
A1: CMMI-DEV Appraisal | T1: CMMI-SVC Appraisal
A2: PI Product Integration | B2: TS Technical Solution | C2: PQA Process Quality Assurance | D2: PR Peer Reviews | E2: RDM Requirements Development and Management | F2: VV Verification and Validation | G2: MPM Managing Performance and Measurement | H2: PAD Process Asset Development | I2: PCM Process Management | J2: RSK Risk and Opportunity Management | K2: OT Organizational Training | L2: EST Estimating | M2: MC Monitor and Control | N2: PLAN Planning | O2: CAR Causal Analysis and Resolution | P2: CM Configuration Management | Q2: DAR Decision Analysis and Resolution | R2: SAM Supplier Agreement Management | T2: SDM Service Delivery Management | U2: STSM Strategic Service Management | V2: PQA Process Quality Assurance | W2: PR Peer Reviews | X2: RDM Requirements Development and Management | Y2: VV Verification and Validation | Z2: MPM Managing Performance and Measurement | AA2: PAD Process Asset Development | AB2: PCM Process Management | AC2: CONT Continuity | AD2: IRP Incident Resolution and Prevention | AE2: RSK Risk and Opportunity Management | AF2: OT Organizational Training | AG2: EST Estimating | AH2: MC Monitor and Control | AI2: PLAN Planning | AJ2: CAR Causal Analysis and Resolution | AK2: CM Configuration Management | AL2: DAR Decision Analysis and Resolution | AM2: SAM Supplier Agreement Management
A3: CL0 | B3: CL0 | C3: CL0 | D3: CL0 | E3: CL0 | F3: CL0 | G3: CL0 | H3: CL0 | I3: CL0 | J3: CL0 | K3: CL0 | L3: CL0 | M3: CL0 | N3: CL0 | O3: CL0 | P3: CL0 | Q3: CL0 | R3: CL0 | T3: CL0 | U3: CL0 | V3: CL0 | W3: CL0 | X3: CL0 | Y3: CL0 | Z3: CL0 | AA3: CL0 | AB3: CL0 | AC3: CL0 | AD3: CL0 | AE3: CL0 | AF3: CL0 | AG3: CL0 | AH3: CL0 | AI3: CL0 | AJ3: CL0 | AK3: CL0 | AL3: CL0 | AM3: CL0
A50: CL0
A51: CL1
A52: CL2
A53: CL3

Sheet T3-Support Functions
A1: Database ID (blank for new records) | B1: Org Support Function Name (required) | C1: Project Type | D1: Size (FTEs) (required) | E1: Brief Function Description | F1: Is this function sensitive? (required) | G1: Point of Contact (required if project marked sensitive) | H1: Point of Contact's email address (required if project marked sensitive) | I1: Function Solution Domain | J1: Function Uses Suppliers (required) | K1: Current Function Manager's Name(s) | L1: Address Line 1 | M1: Address Line 2 | N1: City | O1: State/Province/Region | P1: ZIP/Postal Code | Q1: Country | R1: Additional Function Information
B2: EPG | D2: 5 | E2: Group primarily responsible for performance improvement. | F2: No | I2: All projects | J2: No | K2: Ed Pareto Gamma | N2: Beijing | Q2: China
B3: Training Group | D3: 3 | E3: Group primarily responsible for enhancing skills and knowledge. | F3: No | I3: All projects | J3: No | K3: Olivia Tetrus | N3: Moscow | Q3: Russia
B4: Configuration Management Group | D4: 4 | E4: Group that facilitates CM activities | F4: No | I4: All projects | J4: No | K4: Charles Munson | N4: Paris | Q4: France
B5: Process Assurance Group | D5: 3 | E5: Group that ensure compliance to work product standards and processes. | F5: No | I5: All projects | J5: No | K5: Processo Grupa | N5: Madrid | Q5: Spain

Sheet T4-Projects
A1: Database ID (blank for new records) | B1: Project Name (Not Updatable) | C1: Project Type | D1: Size (FTEs) (required) | E1: Brief Project Description (required) | F1: Is this project sensitive? (required) | G1: Point of Contact (required if project marked sensitive) | H1: Point of Contact's email address (required if project marked sensitive) | I1: Project Solution Domain (required) | J1: Business and Performance Objectives (required for Org Unit Projects only) | K1: Current Life Cycle Phase (required for Org Unit Projects only) | L1: Project Start Date (required for Org Unit Projects only) | M1: Project Projected End Date (required for Org Unit Projects only) | N1: Project Uses Suppliers (required) | O1: Current Project Manager's Name(s) (required) | P1: Address Line 1 (required) | Q1: Address Line 2 | R1: City (required) | S1: State/ Province/ Region | T1: ZIP/Postal Code | U1: Country (required) | V1: Additional Project Information
B2: Arizona Project | D2: 37 | F2: No | L2: 2020/2/6 | M2: 2021/10/19 | N2: No | O2: John Adams
B3: Florida Project | D3: 53 | F3: No | L3: 2020/6/25 | M3: 2021/11/13 | N3: No | O3: Thomas Jefferson
B4: South Carolina Project | D4: 42 | F4: No | L4: 2019/1/9 | M4: 2021/1/24 | N4: No | O4: Aaron Burr
B5: West Virginia Project | D5: 35 | F5: No | L5: 2018/6/26 | M5: 2021/9/20 | N5: No | O5: George Clinton
B6: Massachusetts Project | D6: 52 | F6: No | L6: 2020/1/19 | M6: 2022/5/25 | N6: No | O6: George Clinton
B7: Mississippi Project | D7: 50 | F7: No | L7: 2018/1/17 | M7: 2021/4/18 | N7: No | O7: Elbridge Gerry
B8: Delaware Project | D8: 17 | F8: No | L8: 2019/10/22 | M8: 2022/10/26 | N8: No | O8: Daniel Tompkins
B9: Hawaii Project | D9: 40 | F9: Yes | G9: Honolulu Jack | H9: Honolulu.Jack@ACME.com | L9: 2018/9/13 | M9: 2021/7/18 | N9: No | O9: John C. Calhoun
B10: Louisiana Project | D10: 11 | F10: No | L10: 2020/1/12 | M10: 2021/8/3 | N10: No | O10: John C. Calhoun
B11: PennsylvaniaRhode Island Project | D11: 42 | F11: No | L11: 2020/3/5 | M11: 2023/3/7 | N11: No | O11: Martin Van Buren
B12: Oregon Project | D12: 47 | F12: No | L12: 2018/9/5 | M12: 2021/7/16 | N12: No | O12: Richard M. Johnson
B13: New Hampshire Project | D13: 20 | F13: No | L13: 2020/6/13 | M13: 2022/10/21 | N13: No | O13: John Tyler
B14: IllinoisIndiana Project | D14: 43 | F14: No | L14: 2020/2/8 | M14: 2021/5/8 | N14: No | O14: George M. Dallas
B15: New Mexico Project | D15: 32 | F15: No | L15: 2019/2/2 | M15: 2020/6/7 | N15: No | O15: Millard Fillmore
B16: Kentucky Project | D16: 18 | F16: No | L16: 2019/10/13 | M16: 2021/2/13 | N16: No | O16: William R. King
B17: MontanaNebraska Project | D17: 26 | F17: No | L17: 2018/3/30 | M17: 2021/1/23 | N17: No | O17: John C. Breckinridge
B18: Arkansas Project | D18: 23 | F18: No | L18: 2019/5/7 | M18: 2021/9/28 | N18: No | O18: Hannibal Hamlin
B19: Alabama Project | D19: 39 | F19: No | L19: 2020/3/8 | M19: 2023/5/11 | N19: No | O19: Andrew Johnson
B20: North Carolina Project | D20: 18 | F20: No | L20: 2020/6/16 | M20: 2021/8/28 | N20: No | O20: Schuyler Colfax
B21: Washington Project | D21: 10 | F21: Yes | G21: Seattle Sam | H21: Seattle.Sam@ACME.com | L21: 2019/10/19 | M21: 2020/1/8 | N21: No | O21: Henry Wilson
B22: Missouri Project | D22: 45 | F22: No | L22: 2020/6/8 | M22: 2023/2/27 | N22: No | O22: William Wheeler
B23: North Dakota Project | D23: 14 | F23: No | L23: 2019/12/5 | M23: 2022/6/4 | N23: No | O23: Chester Arthur
B24: Kansas Project | D24: 46 | F24: No | L24: 2019/12/9 | M24: 2021/6/26 | N24: No | O24: Thomas A. Hendricks
B25: South Dakota Project | D25: 26 | F25: No | L25: 2018/7/16 | M25: 2020/11/20 | N25: No | O25: Levi P. Morton
B26: California Project | D26: 38 | F26: No | L26: 2019/8/17 | M26: 2020/8/6 | N26: No | O26: Adlai E. Stevenson
B27: Oklahoma Project | D27: 30 | F27: No | L27: 2020/4/17 | M27: 2022/5/27 | N27: No | O27: Garret A. Hobart
B28: Georgia Project | D28: 26 | F28: No | L28: 2019/12/23 | M28: 2020/5/30 | N28: No | O28: Theodore Roosevelt
B29: Connecticut Project | D29: 47 | F29: No | L29: 2018/9/30 | M29: 2022/9/6 | N29: No | O29: Charles Fairbanks
B30: Ohio Project | D30: 10 | F30: No | L30: 2019/4/21 | M30: 2022/5/8 | N30: No | O30: James Sherman
B31: New Jersey Project | D31: 54 | F31: No | L31: 2019/3/1 | M31: 2022/7/17 | N31: No | O31: Thomas R. Marshall
B32: Tennessee Project | D32: 19 | F32: No | L32: 2019/9/13 | M32: 2021/6/20 | N32: No | O32: Calvin Coolidge
B33: Virginia Project | D33: 37 | F33: No | L33: 2019/12/29 | M33: 2020/10/12 | N33: No | O33: Charles Dawes
... B38: Maryland Project | D38: 18 | F38: No | L38: 2020/3/22 | M38: 2023/8/15 | N38: No | O38: Alben Barkley

Sheet X-Sampling Factors
A1: Notes:
A2: 1. Sampling factors are "relevant" if they lead to process being performed in fundamentally different ways.
A3: A. For example, if the org has Waterfall projects and Agile projects, "Type of Work" would be a relevant sampling factor.
A4: 2. If this is a re-appraisal, the lead appraiser should populate the table below with the values from the previous appraisal.
A7: Candidate Sampling Factor | B7: Relevant? (Y/N) | C7: Sampling Factor Values | D7: Explanation
A8: Location | B8: N
A9: Size | B9: N
A10: Customer | B10: N
A11: Organizational Structure | B11: N
A12: Type of Work | B12: Y | C12: Development vs. Aplication Management & Support (AMS)
A13: Life Cycle | B13: Y | C13: Waterfall, Agile, Kanban
A14: <Other #2>
A16: Subgroups are combinations of sampling factors that represent one or more projects.
A17: (See example below and then list populated Subgroups here)
A19: Development/Waterfall
A20: Development/Agile
A21: AMS/Kanban
A27: EXAMPLE:
A29: Candidate Sampling Factor | B29: Relevant? (Y/N) | C29: Sampling Factor Values | D29: Explanation
A30: Location | B30: Y | C30: Chicago, Mumbai, Beijing | D30: Work is performed differently in each location.
A31: Size | B31: N | D31: Project processes are not affected by the size of the project.
A32: Customer | B32: Y | C32: Government, Commercial | D32: Work is performed differently depending on the type of customer.
A33: Organizational Structure | B33: N | D33: There is only 1 org structure in the appraisal scope.
A34: Type of Work | B34: Y | C34: Waterfall, Agile | D34: Two fundamentally different life cycles are used to perform the work.
A35: <Other #1>
A36: <Other #2>
A39: Possible subgroups are:
A40: Chicago, Government, Waterfall
A41: Chicago, Government, Agile
A42: Chicago, Commercial, Waterfall
A43: Chicago, Commercial, Agile
A44: Mumbai, Government, Waterfall
A45: Mumbai, Government, Agile
A46: Mumbai, Commercial, Waterfall
A47: Mumbai, Commercial, Agile
A48: Beijing, Government, Waterfall
... A58: Essentially, they are unique combinations of the key project attributes that need to be sampled to get a proper portfolio view of development/service activites.

Sheet T5-Subgroup Assignments
A1: Project (Copy list of projects from [T-4 Projects]) | B1: Subgroup | E1: Note: Download the Excel template from CAS and then indicate the subgroup associated with
A2: Alabama Project | B2: 2503 - Development/Agile (Development/Agile)
A3: Arizona Project | B3: 2503 - Development/Agile (Development/Agile) | E3: each project.
A4: Arkansas Project | B4: 2502 - Development/Waterfall (Development/Waterfall)
A5: California Project | B5: 2503 - Development/Agile (Development/Agile)
A6: Connecticut Project | B6: 2502 - Development/Waterfall (Development/Waterfall)
A7: Delaware Project | B7: 2502 - Development/Waterfall (Development/Waterfall)
A8: Florida Project | B8: 2503 - Development/Agile (Development/Agile)
A9: Georgia Project | B9: 2503 - Development/Agile (Development/Agile)
A10: Hawaii Project | B10: 2503 - Development/Agile (Development/Agile)
A11: IllinoisIndiana Project | B11: 2502 - Development/Waterfall (Development/Waterfall)
A12: Kansas Project | B12: 2502 - Development/Waterfall (Development/Waterfall)
A13: Kentucky Project | B13: 2503 - Development/Agile (Development/Agile)
A14: Louisiana Project | B14: 2503 - Development/Agile (Development/Agile)
A15: Maryland Project | B15: 2504 - AMS/Kanban (AMS/Kanban)
... A38: Wisconsin Project | B38: 2503 - Development/Agile (Development/Agile)

Sheet X-Support Function Exceptions
B1: CMMI-DEV Appraisal | V1: CMMI-SVC Appraisal
A2: Support Function (Copy list of support functions from [T-3 Support Functions]) | B2: PI Product Integration | C2: TS Technical Solution | D2: PQA Process Quality Assurance | E2: PR Peer Reviews | F2: RDM Requirements Development and Management | G2: VV Verification and Validation | H2: MPM Managing Performance and Measurement | I2: PAD Process Asset Development | J2: PCM Process Management | K2: RSK Risk and Opportunity Management | L2: OT Organizational Training | M2: EST Estimating | N2: MC Monitor and Control | O2: PLAN Planning | P2: CAR Causal Analysis and Resolution | Q2: CM Configuration Management | R2: DAR Decision Analysis and Resolution | S2: SAM Supplier Agreement Management | T2: Explanation for "In-Scope" and "In-Scope(Exclusive)" Practice Areas | V2: SDM Service Delivery Management | W2: STSM Strategic Service Management | X2: PQA Process Quality Assurance | Y2: PR Peer Reviews | Z2: RDM Requirements Development and Management | AA2: VV Verification and Validation | AB2: MPM Managing Performance and Measurement | AC2: PAD Process Asset Development | AD2: PCM Process Management | AE2: CONT Continuity | AF2: IRP Incident Resolution and Prevention | AG2: RSK Risk and Opportunity Management | AH2: OT Organizational Training | AI2: EST Estimating | AJ2: MC Monitor and Control | AK2: PLAN Planning | AL2: CAR Causal Analysis and Resolution | AM2: CM Configuration Management | AN2: DAR Decision Analysis and Resolution | AO2: SAM Supplier Agreement Management | AP2: Explanation for "In-Scope" and "In-Scope(Exclusive)" Practice Areas
A3: EPG | B3: =IF($A3="","","Out-of-Scope") -> Out-of-Scope | C3: =IF($A3="","","Out-of-Scope") -> Out-of-Scope | D3: =IF($A3="","","Out-of-Scope") -> Out-of-Scope | E3: =IF($A3="","","Out-of-Scope") -> Out-of-Scope | F3: =IF($A3="","","Out-of-Scope") -> Out-of-Scope | G3: =IF($A3="","","Out-of-Scope") -> Out-of-Scope | H3: =IF($A3="","","Out-of-Scope") -> Out-of-Scope | I3: In-Scope(Exclusive) | J3: In-Scope(Exclusive) | K3: =IF($A3="","","Out-of-Scope") -> Out-of-Scope | L3: =IF($A3="","","Out-of-Scope") -> Out-of-Scope | M3: =IF($A3="","","Out-of-Scope") -> Out-of-Scope | N3: =IF($A3="","","Out-of-Scope") -> Out-of-Scope | O3: =IF($A3="","","Out-of-Scope") -> Out-of-Scope | P3: In-Scope | Q3: =IF($A3="","","Out-of-Scope") -> Out-of-Scope | R3: In-Scope | S3: =IF($A3="","","Out-of-Scope") -> Out-of-Scope | T3: The EPG is the only group that does these PAD/PCM-related activities. The EPG uses DAR to prioritize candidate improvements The EPG uses CAR to analyze systemic issues. | V3: =IF($A3="","","Out-of-Scope") -> Out-of-Scope | W3: =IF($A3="","","Out-of-Scope") -> Out-of-Scope | X3: =IF($A3="","","Out-of-Scope") -> Out-of-Scope | Y3: =IF($A3="","","Out-of-Scope") -> Out-of-Scope | Z3: =IF($A3="","","Out-of-Scope") -> Out-of-Scope | AA3: =IF($A3="","","Out-of-Scope") -> Out-of-Scope | AB3: =IF($A3="","","Out-of-Scope") -> Out-of-Scope | AC3: =IF($A3="","","Out-of-Scope") -> Out-of-Scope | ... AO3: =IF($A3="","","Out-of-Scope") -> Out-of-Scope
A4: Training Group | B4: =IF($A4="","","Out-of-Scope") -> Out-of-Scope | C4: =IF($A4="","","Out-of-Scope") -> Out-of-Scope | D4: =IF($A4="","","Out-of-Scope") -> Out-of-Scope | E4: =IF($A4="","","Out-of-Scope") -> Out-of-Scope | F4: =IF($A4="","","Out-of-Scope") -> Out-of-Scope | G4: =IF($A4="","","Out-of-Scope") -> Out-of-Scope | H4: =IF($A4="","","Out-of-Scope") -> Out-of-Scope | I4: =IF($A4="","","Out-of-Scope") -> Out-of-Scope | ... K4: =IF($A4="","","Out-of-Scope") -> Out-of-Scope | L4: In-Scope(Exclusive) | M4: =IF($A4="","","Out-of-Scope") -> Out-of-Scope | N4: =IF($A4="","","Out-of-Scope") -> Out-of-Scope | O4: =IF($A4="","","Out-of-Scope") -> Out-of-Scope | P4: =IF($A4="","","Out-of-Scope") -> Out-of-Scope | Q4: =IF($A4="","","Out-of-Scope") -> Out-of-Scope | R4: =IF($A4="","","Out-of-Scope") -> Out-of-Scope | S4: =IF($A4="","","Out-of-Scope") -> Out-of-Scope | T4: Training Group is the only group thar facilitates OT-related activities. | V4: =IF($A4="","","Out-of-Scope") -> Out-of-Scope | W4: =IF($A4="","","Out-of-Scope") -> Out-of-Scope | X4: =IF($A4="","","Out-of-Scope") -> Out-of-Scope | Y4: =IF($A4="","","Out-of-Scope") -> Out-of-Scope | Z4: =IF($A4="","","Out-of-Scope") -> Out-of-Scope | AA4: =IF($A4="","","Out-of-Scope") -> Out-of-Scope | AB4: =IF($A4="","","Out-of-Scope") -> Out-of-Scope | AC4: =IF($A4="","","Out-of-Scope") -> Out-of-Scope | ... AO4: =IF($A4="","","Out-of-Scope") -> Out-of-Scope
A5: Configuration Management Group | B5: =IF($A5="","","Out-of-Scope") -> Out-of-Scope | C5: =IF($A5="","","Out-of-Scope") -> Out-of-Scope | D5: =IF($A5="","","Out-of-Scope") -> Out-of-Scope | E5: =IF($A5="","","Out-of-Scope") -> Out-of-Scope | F5: =IF($A5="","","Out-of-Scope") -> Out-of-Scope | G5: =IF($A5="","","Out-of-Scope") -> Out-of-Scope | H5: =IF($A5="","","Out-of-Scope") -> Out-of-Scope | I5: =IF($A5="","","Out-of-Scope") -> Out-of-Scope | ... P5: =IF($A5="","","Out-of-Scope") -> Out-of-Scope | Q5: In-Scope | R5: =IF($A5="","","Out-of-Scope") -> Out-of-Scope | S5: =IF($A5="","","Out-of-Scope") -> Out-of-Scope | T5: CM facilitates many of the CM-related activities. | V5: =IF($A5="","","Out-of-Scope") -> Out-of-Scope | W5: =IF($A5="","","Out-of-Scope") -> Out-of-Scope | X5: =IF($A5="","","Out-of-Scope") -> Out-of-Scope | Y5: =IF($A5="","","Out-of-Scope") -> Out-of-Scope | Z5: =IF($A5="","","Out-of-Scope") -> Out-of-Scope | AA5: =IF($A5="","","Out-of-Scope") -> Out-of-Scope | AB5: =IF($A5="","","Out-of-Scope") -> Out-of-Scope | AC5: =IF($A5="","","Out-of-Scope") -> Out-of-Scope | ... AL5: =IF($A5="","","Out-of-Scope") -> Out-of-Scope | AO5: =IF($A5="","","Out-of-Scope") -> Out-of-Scope
A6: Process Assurance Group | B6: =IF($A6="","","Out-of-Scope") -> Out-of-Scope | C6: =IF($A6="","","Out-of-Scope") -> Out-of-Scope | D6: In-Scope | E6: =IF($A6="","","Out-of-Scope") -> Out-of-Scope | F6: =IF($A6="","","Out-of-Scope") -> Out-of-Scope | G6: =IF($A6="","","Out-of-Scope") -> Out-of-Scope | H6: In-Scope | I6: =IF($A6="","","Out-of-Scope") -> Out-of-Scope | J6: =IF($A6="","","Out-of-Scope") -> Out-of-Scope | K6: =IF($A6="","","Out-of-Scope") -> Out-of-Scope | L6: =IF($A6="","","Out-of-Scope") -> Out-of-Scope | M6: =IF($A6="","","Out-of-Scope") -> Out-of-Scope | N6: =IF($A6="","","Out-of-Scope") -> Out-of-Scope | O6: =IF($A6="","","Out-of-Scope") -> Out-of-Scope | P6: =IF($A6="","","Out-of-Scope") -> Out-of-Scope | ... S6: =IF($A6="","","Out-of-Scope") -> Out-of-Scope | T6: PAG performs many of the PQA-related activities. PAG uses MPM-related activities to conduct trend analysis. | V6: =IF($A6="","","Out-of-Scope") -> Out-of-Scope | W6: =IF($A6="","","Out-of-Scope") -> Out-of-Scope | X6: =IF($A6="","","Out-of-Scope") -> Out-of-Scope | Y6: =IF($A6="","","Out-of-Scope") -> Out-of-Scope | Z6: =IF($A6="","","Out-of-Scope") -> Out-of-Scope | AA6: =IF($A6="","","Out-of-Scope") -> Out-of-Scope | AB6: =IF($A6="","","Out-of-Scope") -> Out-of-Scope | AC6: =IF($A6="","","Out-of-Scope") -> Out-of-Scope | ... AL6: =IF($A6="","","Out-of-Scope") -> Out-of-Scope | AO6: =IF($A6="","","Out-of-Scope") -> Out-of-Scope
B7: =IF($A7="","","Out-of-Scope") | C7: =IF($A7="","","Out-of-Scope") | D7: =IF($A7="","","Out-of-Scope") | E7: =IF($A7="","","Out-of-Scope") | F7: =IF($A7="","","Out-of-Scope") | G7: =IF($A7="","","Out-of-Scope") | H7: =IF($A7="","","Out-of-Scope") | I7: =IF($A7="","","Out-of-Scope") | ... S7: =IF($A7="","","Out-of-Scope") | V7: =IF($A7="","","Out-of-Scope") | W7: =IF($A7="","","Out-of-Scope") | X7: =IF($A7="","","Out-of-Scope") | Y7: =IF($A7="","","Out-of-Scope") | Z7: =IF($A7="","","Out-of-Scope") | AA7: =IF($A7="","","Out-of-Scope") | AB7: =IF($A7="","","Out-of-Scope") | AC7: =IF($A7="","","Out-of-Scope") | ... AL7: =IF($A7="","","Out-of-Scope") | AO7: =IF($A7="","","Out-of-Scope")
B8: =IF($A8="","","Out-of-Scope") | C8: =IF($A8="","","Out-of-Scope") | D8: =IF($A8="","","Out-of-Scope") | E8: =IF($A8="","","Out-of-Scope") | F8: =IF($A8="","","Out-of-Scope") | G8: =IF($A8="","","Out-of-Scope") | H8: =IF($A8="","","Out-of-Scope") | I8: =IF($A8="","","Out-of-Scope") | ... S8: =IF($A8="","","Out-of-Scope") | V8: =IF($A8="","","Out-of-Scope") | W8: =IF($A8="","","Out-of-Scope") | X8: =IF($A8="","","Out-of-Scope") | Y8: =IF($A8="","","Out-of-Scope") | Z8: =IF($A8="","","Out-of-Scope") | AA8: =IF($A8="","","Out-of-Scope") | AB8: =IF($A8="","","Out-of-Scope") | AC8: =IF($A8="","","Out-of-Scope") | ... AL8: =IF($A8="","","Out-of-Scope") | AO8: =IF($A8="","","Out-of-Scope")
B9: =IF($A9="","","Out-of-Scope") | C9: =IF($A9="","","Out-of-Scope") | D9: =IF($A9="","","Out-of-Scope") | E9: =IF($A9="","","Out-of-Scope") | F9: =IF($A9="","","Out-of-Scope") | G9: =IF($A9="","","Out-of-Scope") | H9: =IF($A9="","","Out-of-Scope") | I9: =IF($A9="","","Out-of-Scope") | ... S9: =IF($A9="","","Out-of-Scope") | V9: =IF($A9="","","Out-of-Scope") | W9: =IF($A9="","","Out-of-Scope") | X9: =IF($A9="","","Out-of-Scope") | Y9: =IF($A9="","","Out-of-Scope") | Z9: =IF($A9="","","Out-of-Scope") | AA9: =IF($A9="","","Out-of-Scope") | AB9: =IF($A9="","","Out-of-Scope") | AC9: =IF($A9="","","Out-of-Scope") | ... AL9: =IF($A9="","","Out-of-Scope") | AO9: =IF($A9="","","Out-of-Scope")
B10: =IF($A10="","","Out-of-Scope") | C10: =IF($A10="","","Out-of-Scope") | D10: =IF($A10="","","Out-of-Scope") | E10: =IF($A10="","","Out-of-Scope") | F10: =IF($A10="","","Out-of-Scope") | G10: =IF($A10="","","Out-of-Scope") | H10: =IF($A10="","","Out-of-Scope") | I10: =IF($A10="","","Out-of-Scope") | ... S10: =IF($A10="","","Out-of-Scope") | V10: =IF($A10="","","Out-of-Scope") | W10: =IF($A10="","","Out-of-Scope") | X10: =IF($A10="","","Out-of-Scope") | Y10: =IF($A10="","","Out-of-Scope") | Z10: =IF($A10="","","Out-of-Scope") | AA10: =IF($A10="","","Out-of-Scope") | AB10: =IF($A10="","","Out-of-Scope") | AC10: =IF($A10="","","Out-of-Scope") | ... AL10: =IF($A10="","","Out-of-Scope") | AO10: =IF($A10="","","Out-of-Scope")
B11: =IF($A11="","","Out-of-Scope") | C11: =IF($A11="","","Out-of-Scope") | D11: =IF($A11="","","Out-of-Scope") | E11: =IF($A11="","","Out-of-Scope") | F11: =IF($A11="","","Out-of-Scope") | G11: =IF($A11="","","Out-of-Scope") | H11: =IF($A11="","","Out-of-Scope") | I11: =IF($A11="","","Out-of-Scope") | ... S11: =IF($A11="","","Out-of-Scope") | V11: =IF($A11="","","Out-of-Scope") | W11: =IF($A11="","","Out-of-Scope") | X11: =IF($A11="","","Out-of-Scope") | Y11: =IF($A11="","","Out-of-Scope") | Z11: =IF($A11="","","Out-of-Scope") | AA11: =IF($A11="","","Out-of-Scope") | AB11: =IF($A11="","","Out-of-Scope") | AC11: =IF($A11="","","Out-of-Scope") | ... AL11: =IF($A11="","","Out-of-Scope") | AO11: =IF($A11="","","Out-of-Scope")
B12: =IF($A12="","","Out-of-Scope") | C12: =IF($A12="","","Out-of-Scope") | D12: =IF($A12="","","Out-of-Scope") | E12: =IF($A12="","","Out-of-Scope") | F12: =IF($A12="","","Out-of-Scope") | G12: =IF($A12="","","Out-of-Scope") | H12: =IF($A12="","","Out-of-Scope") | I12: =IF($A12="","","Out-of-Scope") | ... S12: =IF($A12="","","Out-of-Scope") | V12: =IF($A12="","","Out-of-Scope") | W12: =IF($A12="","","Out-of-Scope") | X12: =IF($A12="","","Out-of-Scope") | Y12: =IF($A12="","","Out-of-Scope") | Z12: =IF($A12="","","Out-of-Scope") | AA12: =IF($A12="","","Out-of-Scope") | AB12: =IF($A12="","","Out-of-Scope") | AC12: =IF($A12="","","Out-of-Scope") | ... AL12: =IF($A12="","","Out-of-Scope") | AO12: =IF($A12="","","Out-of-Scope")
B13: =IF($A13="","","Out-of-Scope") | C13: =IF($A13="","","Out-of-Scope") | D13: =IF($A13="","","Out-of-Scope") | E13: =IF($A13="","","Out-of-Scope") | F13: =IF($A13="","","Out-of-Scope") | G13: =IF($A13="","","Out-of-Scope") | H13: =IF($A13="","","Out-of-Scope") | I13: =IF($A13="","","Out-of-Scope") | ... S13: =IF($A13="","","Out-of-Scope") | V13: =IF($A13="","","Out-of-Scope") | W13: =IF($A13="","","Out-of-Scope") | X13: =IF($A13="","","Out-of-Scope") | Y13: =IF($A13="","","Out-of-Scope") | Z13: =IF($A13="","","Out-of-Scope") | AA13: =IF($A13="","","Out-of-Scope") | AB13: =IF($A13="","","Out-of-Scope") | AC13: =IF($A13="","","Out-of-Scope") | ... AL13: =IF($A13="","","Out-of-Scope") | AO13: =IF($A13="","","Out-of-Scope")
B14: =IF($A14="","","Out-of-Scope") | C14: =IF($A14="","","Out-of-Scope") | D14: =IF($A14="","","Out-of-Scope") | E14: =IF($A14="","","Out-of-Scope") | F14: =IF($A14="","","Out-of-Scope") | G14: =IF($A14="","","Out-of-Scope") | H14: =IF($A14="","","Out-of-Scope") | I14: =IF($A14="","","Out-of-Scope") | ... S14: =IF($A14="","","Out-of-Scope") | V14: =IF($A14="","","Out-of-Scope") | W14: =IF($A14="","","Out-of-Scope") | X14: =IF($A14="","","Out-of-Scope") | Y14: =IF($A14="","","Out-of-Scope") | Z14: =IF($A14="","","Out-of-Scope") | AA14: =IF($A14="","","Out-of-Scope") | AB14: =IF($A14="","","Out-of-Scope") | AC14: =IF($A14="","","Out-of-Scope") | ... AL14: =IF($A14="","","Out-of-Scope") | AO14: =IF($A14="","","Out-of-Scope")
B15: =IF($A15="","","Out-of-Scope") | C15: =IF($A15="","","Out-of-Scope") | D15: =IF($A15="","","Out-of-Scope") | E15: =IF($A15="","","Out-of-Scope") | F15: =IF($A15="","","Out-of-Scope") | G15: =IF($A15="","","Out-of-Scope") | H15: =IF($A15="","","Out-of-Scope") | I15: =IF($A15="","","Out-of-Scope") | ... S15: =IF($A15="","","Out-of-Scope") | V15: =IF($A15="","","Out-of-Scope") | W15: =IF($A15="","","Out-of-Scope") | X15: =IF($A15="","","Out-of-Scope") | Y15: =IF($A15="","","Out-of-Scope") | Z15: =IF($A15="","","Out-of-Scope") | AA15: =IF($A15="","","Out-of-Scope") | AB15: =IF($A15="","","Out-of-Scope") | AC15: =IF($A15="","","Out-of-Scope") | ... AL15: =IF($A15="","","Out-of-Scope") | AO15: =IF($A15="","","Out-of-Scope")
B16: =IF($A16="","","Out-of-Scope") | C16: =IF($A16="","","Out-of-Scope") | D16: =IF($A16="","","Out-of-Scope") | E16: =IF($A16="","","Out-of-Scope") | F16: =IF($A16="","","Out-of-Scope") | G16: =IF($A16="","","Out-of-Scope") | H16: =IF($A16="","","Out-of-Scope") | I16: =IF($A16="","","Out-of-Scope") | ... S16: =IF($A16="","","Out-of-Scope") | V16: =IF($A16="","","Out-of-Scope") | W16: =IF($A16="","","Out-of-Scope") | X16: =IF($A16="","","Out-of-Scope") | Y16: =IF($A16="","","Out-of-Scope") | Z16: =IF($A16="","","Out-of-Scope") | AA16: =IF($A16="","","Out-of-Scope") | AB16: =IF($A16="","","Out-of-Scope") | AC16: =IF($A16="","","Out-of-Scope") | ... AL16: =IF($A16="","","Out-of-Scope") | AO16: =IF($A16="","","Out-of-Scope")
B17: =IF($A17="","","Out-of-Scope") | C17: =IF($A17="","","Out-of-Scope") | D17: =IF($A17="","","Out-of-Scope") | E17: =IF($A17="","","Out-of-Scope") | F17: =IF($A17="","","Out-of-Scope") | G17: =IF($A17="","","Out-of-Scope") | H17: =IF($A17="","","Out-of-Scope") | I17: =IF($A17="","","Out-of-Scope") | ... S17: =IF($A17="","","Out-of-Scope") | V17: =IF($A17="","","Out-of-Scope") | W17: =IF($A17="","","Out-of-Scope") | X17: =IF($A17="","","Out-of-Scope") | Y17: =IF($A17="","","Out-of-Scope") | Z17: =IF($A17="","","Out-of-Scope") | AA17: =IF($A17="","","Out-of-Scope") | AB17: =IF($A17="","","Out-of-Scope") | AC17: =IF($A17="","","Out-of-Scope") | ... AL17: =IF($A17="","","Out-of-Scope") | AO17: =IF($A17="","","Out-of-Scope")
B18: =IF($A18="","","Out-of-Scope") | C18: =IF($A18="","","Out-of-Scope") | D18: =IF($A18="","","Out-of-Scope") | E18: =IF($A18="","","Out-of-Scope") | F18: =IF($A18="","","Out-of-Scope") | G18: =IF($A18="","","Out-of-Scope") | H18: =IF($A18="","","Out-of-Scope") | I18: =IF($A18="","","Out-of-Scope") | ... S18: =IF($A18="","","Out-of-Scope") | V18: =IF($A18="","","Out-of-Scope") | W18: =IF($A18="","","Out-of-Scope") | X18: =IF($A18="","","Out-of-Scope") | Y18: =IF($A18="","","Out-of-Scope") | Z18: =IF($A18="","","Out-of-Scope") | AA18: =IF($A18="","","Out-of-Scope") | AB18: =IF($A18="","","Out-of-Scope") | AC18: =IF($A18="","","Out-of-Scope") | ... AL18: =IF($A18="","","Out-of-Scope") | AO18: =IF($A18="","","Out-of-Scope")
... B52: =IF($A52="","","Out-of-Scope") | C52: =IF($A52="","","Out-of-Scope") | D52: =IF($A52="","","Out-of-Scope") | E52: =IF($A52="","","Out-of-Scope") | F52: =IF($A52="","","Out-of-Scope") | G52: =IF($A52="","","Out-of-Scope") | H52: =IF($A52="","","Out-of-Scope") | I52: =IF($A52="","","Out-of-Scope") | ... S52: =IF($A52="","","Out-of-Scope") | V52: =IF($A52="","","Out-of-Scope") | W52: =IF($A52="","","Out-of-Scope") | X52: =IF($A52="","","Out-of-Scope") | Y52: =IF($A52="","","Out-of-Scope") | Z52: =IF($A52="","","Out-of-Scope") | AA52: =IF($A52="","","Out-of-Scope") | AB52: =IF($A52="","","Out-of-Scope") | AC52: =IF($A52="","","Out-of-Scope") | ... AL52: =IF($A52="","","Out-of-Scope") | AO52: =IF($A52="","","Out-of-Scope")

Sheet X-Project Exceptions
B1: CMMI-DEV Appraisals | V1: CMMI-SVC Appraisals
A2: Project Name (Copy list of projects from [T-4 Projects]) | B2: PI Product Integration | C2: TS Technical Solution | D2: PQA Process Quality Assurance | E2: PR Peer Reviews | F2: RDM Requirements Development and Management | G2: VV Verification and Validation | H2: MPM Managing Performance and Measurement | I2: PAD Process Asset Development | J2: PCM Process Management | K2: RSK Risk and Opportunity Management | L2: OT Organizational Training | M2: EST Estimating | N2: MC Monitor and Control | O2: PLAN Planning | P2: CAR Causal Analysis and Resolution | Q2: CM Configuration Management | R2: DAR Decision Analysis and Resolution | S2: SAM Supplier Agreement Management | T2: Explanation for any Practice Area other than "In-Scope" | V2: SDM Service Delivery Management | W2: STSM Strategic Service Management | X2: PQA Process Quality Assurance | Y2: PR Peer Reviews | Z2: RDM Requirements Development and Management | AA2: VV Verification and Validation | AB2: MPM Managing Performance and Measurement | AC2: PAD Process Asset Development | AD2: PCM Process Management | AE2: CONT Continuity | AF2: IRP Incident Resolution and Prevention | AG2: RSK Risk and Opportunity Management | AH2: OT Organizational Training | AI2: EST Estimating | AJ2: MC Monitor and Control | AK2: PLAN Planning | AL2: CAR Causal Analysis and Resolution | AM2: CM Configuration Management | AN2: DAR Decision Analysis and Resolution | AO2: SAM Supplier Agreement Management | AP2: Explanation for any Practice Area other than "In-Scope"
A3: Arizona Project | B3: =IF($A3="","","In-Scope") -> In-Scope | C3: =IF($A3="","","In-Scope") -> In-Scope | D3: =IF($A3="","","In-Scope") -> In-Scope | E3: =IF($A3="","","In-Scope") -> In-Scope | F3: =IF($A3="","","In-Scope") -> In-Scope | G3: =IF($A3="","","In-Scope") -> In-Scope | H3: =IF($A3="","","In-Scope") -> In-Scope | I3: =IF($A3="","","Out-of-Scope") -> Out-of-Scope | J3: =IF($A3="","","Out-of-Scope") -> Out-of-Scope | K3: =IF($A3="","","In-Scope") -> In-Scope | L3: =IF($A3="","","Out-of-Scope") -> Out-of-Scope | M3: =IF($A3="","","In-Scope") -> In-Scope | N3: =IF($A3="","","In-Scope") -> In-Scope | O3: =IF($A3="","","In-Scope") -> In-Scope | P3: =IF($A3="","","In-Scope") -> In-Scope | Q3: =IF($A3="","","In-Scope") -> In-Scope | R3: =IF($A3="","","In-Scope") -> In-Scope | S3: =IF($A3="","","In-Scope") -> In-Scope | V3: =IF($A3="","","In-Scope") -> In-Scope | W3: =IF($A3="","","In-Scope") -> In-Scope | X3: =IF($A3="","","In-Scope") -> In-Scope | Y3: =IF($A3="","","In-Scope") -> In-Scope | Z3: =IF($A3="","","In-Scope") -> In-Scope | AA3: =IF($A3="","","In-Scope") -> In-Scope | AB3: =IF($A3="","","In-Scope") -> In-Scope | AC3: =IF($A3="","","In-Scope") -> In-Scope | ... AO3: =IF($A3="","","In-Scope") -> In-Scope
A4: Florida Project | B4: =IF($A4="","","In-Scope") -> In-Scope | C4: =IF($A4="","","In-Scope") -> In-Scope | D4: =IF($A4="","","In-Scope") -> In-Scope | E4: =IF($A4="","","In-Scope") -> In-Scope | F4: =IF($A4="","","In-Scope") -> In-Scope | G4: =IF($A4="","","In-Scope") -> In-Scope | H4: =IF($A4="","","In-Scope") -> In-Scope | I4: =IF($A4="","","Out-of-Scope") -> Out-of-Scope | J4: =IF($A4="","","Out-of-Scope") -> Out-of-Scope | K4: =IF($A4="","","In-Scope") -> In-Scope | L4: =IF($A4="","","Out-of-Scope") -> Out-of-Scope | M4: =IF($A4="","","In-Scope") -> In-Scope | N4: =IF($A4="","","In-Scope") -> In-Scope | O4: =IF($A4="","","In-Scope") -> In-Scope | P4: =IF($A4="","","In-Scope") -> In-Scope | Q4: =IF($A4="","","In-Scope") -> In-Scope | R4: =IF($A4="","","In-Scope") -> In-Scope | S4: =IF($A4="","","In-Scope") -> In-Scope | V4: =IF($A4="","","In-Scope") -> In-Scope | W4: =IF($A4="","","In-Scope") -> In-Scope | X4: =IF($A4="","","In-Scope") -> In-Scope | Y4: =IF($A4="","","In-Scope") -> In-Scope | Z4: =IF($A4="","","In-Scope") -> In-Scope | AA4: =IF($A4="","","In-Scope") -> In-Scope | AB4: =IF($A4="","","In-Scope") -> In-Scope | AC4: =IF($A4="","","In-Scope") -> In-Scope | ... AO4: =IF($A4="","","In-Scope") -> In-Scope
A5: South Carolina Project | B5: =IF($A5="","","In-Scope") -> In-Scope | C5: =IF($A5="","","In-Scope") -> In-Scope | D5: =IF($A5="","","In-Scope") -> In-Scope | E5: =IF($A5="","","In-Scope") -> In-Scope | F5: =IF($A5="","","In-Scope") -> In-Scope | G5: =IF($A5="","","In-Scope") -> In-Scope | H5: =IF($A5="","","In-Scope") -> In-Scope | I5: =IF($A5="","","Out-of-Scope") -> Out-of-Scope | J5: =IF($A5="","","Out-of-Scope") -> Out-of-Scope | K5: =IF($A5="","","In-Scope") -> In-Scope | L5: =IF($A5="","","Out-of-Scope") -> Out-of-Scope | M5: =IF($A5="","","In-Scope") -> In-Scope | N5: =IF($A5="","","In-Scope") -> In-Scope | O5: =IF($A5="","","In-Scope") -> In-Scope | P5: =IF($A5="","","In-Scope") -> In-Scope | Q5: =IF($A5="","","In-Scope") -> In-Scope | R5: =IF($A5="","","In-Scope") -> In-Scope | S5: =IF($A5="","","In-Scope") -> In-Scope | V5: =IF($A5="","","In-Scope") -> In-Scope | W5: =IF($A5="","","In-Scope") -> In-Scope | X5: =IF($A5="","","In-Scope") -> In-Scope | Y5: =IF($A5="","","In-Scope") -> In-Scope | Z5: =IF($A5="","","In-Scope") -> In-Scope | AA5: =IF($A5="","","In-Scope") -> In-Scope | AB5: =IF($A5="","","In-Scope") -> In-Scope | AC5: =IF($A5="","","In-Scope") -> In-Scope | ... AO5: =IF($A5="","","In-Scope") -> In-Scope
A6: West Virginia Project | B6: =IF($A6="","","In-Scope") -> In-Scope | C6: =IF($A6="","","In-Scope") -> In-Scope | D6: =IF($A6="","","In-Scope") -> In-Scope | E6: =IF($A6="","","In-Scope") -> In-Scope | F6: =IF($A6="","","In-Scope") -> In-Scope | G6: =IF($A6="","","In-Scope") -> In-Scope | H6: =IF($A6="","","In-Scope") -> In-Scope | I6: =IF($A6="","","Out-of-Scope") -> Out-of-Scope | J6: =IF($A6="","","Out-of-Scope") -> Out-of-Scope | K6: =IF($A6="","","In-Scope") -> In-Scope | L6: =IF($A6="","","Out-of-Scope") -> Out-of-Scope | M6: =IF($A6="","","In-Scope") -> In-Scope | N6: =IF($A6="","","In-Scope") -> In-Scope | O6: =IF($A6="","","In-Scope") -> In-Scope | P6: =IF($A6="","","In-Scope") -> In-Scope | Q6: =IF($A6="","","In-Scope") -> In-Scope | R6: =IF($A6="","","In-Scope") -> In-Scope | S6: =IF($A6="","","In-Scope") -> In-Scope | V6: =IF($A6="","","In-Scope") -> In-Scope | W6: =IF($A6="","","In-Scope") -> In-Scope | X6: =IF($A6="","","In-Scope") -> In-Scope | Y6: =IF($A6="","","In-Scope") -> In-Scope | Z6: =IF($A6="","","In-Scope") -> In-Scope | AA6: =IF($A6="","","In-Scope") -> In-Scope | AB6: =IF($A6="","","In-Scope") -> In-Scope | AC6: =IF($A6="","","In-Scope") -> In-Scope | ... AO6: =IF($A6="","","In-Scope") -> In-Scope
A7: Massachusetts Project | B7: =IF($A7="","","In-Scope") -> In-Scope | C7: =IF($A7="","","In-Scope") -> In-Scope | D7: =IF($A7="","","In-Scope") -> In-Scope | E7: =IF($A7="","","In-Scope") -> In-Scope | F7: =IF($A7="","","In-Scope") -> In-Scope | G7: =IF($A7="","","In-Scope") -> In-Scope | H7: =IF($A7="","","In-Scope") -> In-Scope | I7: =IF($A7="","","Out-of-Scope") -> Out-of-Scope | J7: =IF($A7="","","Out-of-Scope") -> Out-of-Scope | K7: =IF($A7="","","In-Scope") -> In-Scope | L7: =IF($A7="","","Out-of-Scope") -> Out-of-Scope | M7: =IF($A7="","","In-Scope") -> In-Scope | N7: =IF($A7="","","In-Scope") -> In-Scope | O7: =IF($A7="","","In-Scope") -> In-Scope | P7: =IF($A7="","","In-Scope") -> In-Scope | Q7: =IF($A7="","","In-Scope") -> In-Scope | R7: =IF($A7="","","In-Scope") -> In-Scope | S7: =IF($A7="","","In-Scope") -> In-Scope | V7: =IF($A7="","","In-Scope") -> In-Scope | W7: =IF($A7="","","In-Scope") -> In-Scope | X7: =IF($A7="","","In-Scope") -> In-Scope | Y7: =IF($A7="","","In-Scope") -> In-Scope | Z7: =IF($A7="","","In-Scope") -> In-Scope | AA7: =IF($A7="","","In-Scope") -> In-Scope | AB7: =IF($A7="","","In-Scope") -> In-Scope | AC7: =IF($A7="","","In-Scope") -> In-Scope | ... AO7: =IF($A7="","","In-Scope") -> In-Scope
A8: Mississippi Project | B8: =IF($A8="","","In-Scope") -> In-Scope | C8: =IF($A8="","","In-Scope") -> In-Scope | D8: =IF($A8="","","In-Scope") -> In-Scope | E8: =IF($A8="","","In-Scope") -> In-Scope | F8: =IF($A8="","","In-Scope") -> In-Scope | G8: =IF($A8="","","In-Scope") -> In-Scope | H8: =IF($A8="","","In-Scope") -> In-Scope | I8: =IF($A8="","","Out-of-Scope") -> Out-of-Scope | J8: =IF($A8="","","Out-of-Scope") -> Out-of-Scope | K8: =IF($A8="","","In-Scope") -> In-Scope | L8: =IF($A8="","","Out-of-Scope") -> Out-of-Scope | M8: =IF($A8="","","In-Scope") -> In-Scope | N8: =IF($A8="","","In-Scope") -> In-Scope | O8: =IF($A8="","","In-Scope") -> In-Scope | P8: =IF($A8="","","In-Scope") -> In-Scope | Q8: =IF($A8="","","In-Scope") -> In-Scope | R8: =IF($A8="","","In-Scope") -> In-Scope | S8: =IF($A8="","","In-Scope") -> In-Scope | V8: =IF($A8="","","In-Scope") -> In-Scope | W8: =IF($A8="","","In-Scope") -> In-Scope | X8: =IF($A8="","","In-Scope") -> In-Scope | Y8: =IF($A8="","","In-Scope") -> In-Scope | Z8: =IF($A8="","","In-Scope") -> In-Scope | AA8: =IF($A8="","","In-Scope") -> In-Scope | AB8: =IF($A8="","","In-Scope") -> In-Scope | AC8: =IF($A8="","","In-Scope") -> In-Scope | ... AO8: =IF($A8="","","In-Scope") -> In-Scope
A9: Delaware Project | B9: =IF($A9="","","In-Scope") -> In-Scope | C9: =IF($A9="","","In-Scope") -> In-Scope | D9: =IF($A9="","","In-Scope") -> In-Scope | E9: =IF($A9="","","In-Scope") -> In-Scope | F9: =IF($A9="","","In-Scope") -> In-Scope | G9: =IF($A9="","","In-Scope") -> In-Scope | H9: =IF($A9="","","In-Scope") -> In-Scope | I9: =IF($A9="","","Out-of-Scope") -> Out-of-Scope | J9: =IF($A9="","","Out-of-Scope") -> Out-of-Scope | K9: =IF($A9="","","In-Scope") -> In-Scope | L9: =IF($A9="","","Out-of-Scope") -> Out-of-Scope | M9: =IF($A9="","","In-Scope") -> In-Scope | N9: =IF($A9="","","In-Scope") -> In-Scope | O9: =IF($A9="","","In-Scope") -> In-Scope | P9: =IF($A9="","","In-Scope") -> In-Scope | Q9: =IF($A9="","","In-Scope") -> In-Scope | R9: =IF($A9="","","In-Scope") -> In-Scope | S9: =IF($A9="","","In-Scope") -> In-Scope | V9: =IF($A9="","","In-Scope") -> In-Scope | W9: =IF($A9="","","In-Scope") -> In-Scope | X9: =IF($A9="","","In-Scope") -> In-Scope | Y9: =IF($A9="","","In-Scope") -> In-Scope | Z9: =IF($A9="","","In-Scope") -> In-Scope | AA9: =IF($A9="","","In-Scope") -> In-Scope | AB9: =IF($A9="","","In-Scope") -> In-Scope | AC9: =IF($A9="","","In-Scope") -> In-Scope | ... AO9: =IF($A9="","","In-Scope") -> In-Scope
A10: Hawaii Project | B10: =IF($A10="","","In-Scope") -> In-Scope | C10: =IF($A10="","","In-Scope") -> In-Scope | D10: =IF($A10="","","In-Scope") -> In-Scope | E10: =IF($A10="","","In-Scope") -> In-Scope | F10: =IF($A10="","","In-Scope") -> In-Scope | G10: =IF($A10="","","In-Scope") -> In-Scope | H10: =IF($A10="","","In-Scope") -> In-Scope | I10: =IF($A10="","","Out-of-Scope") -> Out-of-Scope | J10: =IF($A10="","","Out-of-Scope") -> Out-of-Scope | K10: =IF($A10="","","In-Scope") -> In-Scope | L10: =IF($A10="","","Out-of-Scope") -> Out-of-Scope | M10: =IF($A10="","","In-Scope") -> In-Scope | N10: =IF($A10="","","In-Scope") -> In-Scope | O10: =IF($A10="","","In-Scope") -> In-Scope | P10: =IF($A10="","","In-Scope") -> In-Scope | Q10: =IF($A10="","","In-Scope") -> In-Scope | R10: =IF($A10="","","In-Scope") -> In-Scope | S10: =IF($A10="","","In-Scope") -> In-Scope | V10: =IF($A10="","","In-Scope") -> In-Scope | W10: =IF($A10="","","In-Scope") -> In-Scope | X10: =IF($A10="","","In-Scope") -> In-Scope | Y10: =IF($A10="","","In-Scope") -> In-Scope | Z10: =IF($A10="","","In-Scope") -> In-Scope | AA10: =IF($A10="","","In-Scope") -> In-Scope | AB10: =IF($A10="","","In-Scope") -> In-Scope | AC10: =IF($A10="","","In-Scope") -> In-Scope | ... AO10: =IF($A10="","","In-Scope") -> In-Scope
A11: Louisiana Project | B11: =IF($A11="","","In-Scope") -> In-Scope | C11: =IF($A11="","","In-Scope") -> In-Scope | D11: =IF($A11="","","In-Scope") -> In-Scope | E11: =IF($A11="","","In-Scope") -> In-Scope | F11: =IF($A11="","","In-Scope") -> In-Scope | G11: =IF($A11="","","In-Scope") -> In-Scope | H11: =IF($A11="","","In-Scope") -> In-Scope | I11: =IF($A11="","","Out-of-Scope") -> Out-of-Scope | J11: =IF($A11="","","Out-of-Scope") -> Out-of-Scope | K11: =IF($A11="","","In-Scope") -> In-Scope | L11: =IF($A11="","","Out-of-Scope") -> Out-of-Scope | M11: =IF($A11="","","In-Scope") -> In-Scope | N11: =IF($A11="","","In-Scope") -> In-Scope | O11: =IF($A11="","","In-Scope") -> In-Scope | P11: =IF($A11="","","In-Scope") -> In-Scope | Q11: =IF($A11="","","In-Scope") -> In-Scope | R11: =IF($A11="","","In-Scope") -> In-Scope | S11: =IF($A11="","","In-Scope") -> In-Scope | V11: =IF($A11="","","In-Scope") -> In-Scope | W11: =IF($A11="","","In-Scope") -> In-Scope | X11: =IF($A11="","","In-Scope") -> In-Scope | Y11: =IF($A11="","","In-Scope") -> In-Scope | Z11: =IF($A11="","","In-Scope") -> In-Scope | AA11: =IF($A11="","","In-Scope") -> In-Scope | AB11: =IF($A11="","","In-Scope") -> In-Scope | AC11: =IF($A11="","","In-Scope") -> In-Scope | ... AO11: =IF($A11="","","In-Scope") -> In-Scope
A12: PennsylvaniaRhode Island Project | B12: =IF($A12="","","In-Scope") -> In-Scope | C12: =IF($A12="","","In-Scope") -> In-Scope | D12: =IF($A12="","","In-Scope") -> In-Scope | E12: =IF($A12="","","In-Scope") -> In-Scope | F12: =IF($A12="","","In-Scope") -> In-Scope | G12: =IF($A12="","","In-Scope") -> In-Scope | H12: =IF($A12="","","In-Scope") -> In-Scope | I12: =IF($A12="","","Out-of-Scope") -> Out-of-Scope | J12: =IF($A12="","","Out-of-Scope") -> Out-of-Scope | K12: =IF($A12="","","In-Scope") -> In-Scope | L12: =IF($A12="","","Out-of-Scope") -> Out-of-Scope | M12: =IF($A12="","","In-Scope") -> In-Scope | N12: =IF($A12="","","In-Scope") -> In-Scope | O12: =IF($A12="","","In-Scope") -> In-Scope | P12: =IF($A12="","","In-Scope") -> In-Scope | Q12: =IF($A12="","","In-Scope") -> In-Scope | R12: =IF($A12="","","In-Scope") -> In-Scope | S12: =IF($A12="","","In-Scope") -> In-Scope | V12: =IF($A12="","","In-Scope") -> In-Scope | W12: =IF($A12="","","In-Scope") -> In-Scope | X12: =IF($A12="","","In-Scope") -> In-Scope | Y12: =IF($A12="","","In-Scope") -> In-Scope | Z12: =IF($A12="","","In-Scope") -> In-Scope | AA12: =IF($A12="","","In-Scope") -> In-Scope | AB12: =IF($A12="","","In-Scope") -> In-Scope | AC12: =IF($A12="","","In-Scope") -> In-Scope | ... AO12: =IF($A12="","","In-Scope") -> In-Scope
A13: Oregon Project | B13: =IF($A13="","","In-Scope") -> In-Scope | C13: =IF($A13="","","In-Scope") -> In-Scope | D13: =IF($A13="","","In-Scope") -> In-Scope | E13: =IF($A13="","","In-Scope") -> In-Scope | F13: =IF($A13="","","In-Scope") -> In-Scope | G13: =IF($A13="","","In-Scope") -> In-Scope | H13: =IF($A13="","","In-Scope") -> In-Scope | I13: =IF($A13="","","Out-of-Scope") -> Out-of-Scope | J13: =IF($A13="","","Out-of-Scope") -> Out-of-Scope | K13: =IF($A13="","","In-Scope") -> In-Scope | L13: =IF($A13="","","Out-of-Scope") -> Out-of-Scope | M13: =IF($A13="","","In-Scope") -> In-Scope | N13: =IF($A13="","","In-Scope") -> In-Scope | O13: =IF($A13="","","In-Scope") -> In-Scope | P13: =IF($A13="","","In-Scope") -> In-Scope | Q13: =IF($A13="","","In-Scope") -> In-Scope | R13: =IF($A13="","","In-Scope") -> In-Scope | S13: =IF($A13="","","In-Scope") -> In-Scope | V13: =IF($A13="","","In-Scope") -> In-Scope | W13: =IF($A13="","","In-Scope") -> In-Scope | X13: =IF($A13="","","In-Scope") -> In-Scope | Y13: =IF($A13="","","In-Scope") -> In-Scope | Z13: =IF($A13="","","In-Scope") -> In-Scope | AA13: =IF($A13="","","In-Scope") -> In-Scope | AB13: =IF($A13="","","In-Scope") -> In-Scope | AC13: =IF($A13="","","In-Scope") -> In-Scope | ... AO13: =IF($A13="","","In-Scope") -> In-Scope
A14: New Hampshire Project | B14: =IF($A14="","","In-Scope") -> In-Scope | C14: =IF($A14="","","In-Scope") -> In-Scope | D14: =IF($A14="","","In-Scope") -> In-Scope | E14: =IF($A14="","","In-Scope") -> In-Scope | F14: =IF($A14="","","In-Scope") -> In-Scope | G14: =IF($A14="","","In-Scope") -> In-Scope | H14: =IF($A14="","","In-Scope") -> In-Scope | I14: =IF($A14="","","Out-of-Scope") -> Out-of-Scope | J14: =IF($A14="","","Out-of-Scope") -> Out-of-Scope | K14: =IF($A14="","","In-Scope") -> In-Scope | L14: =IF($A14="","","Out-of-Scope") -> Out-of-Scope | M14: =IF($A14="","","In-Scope") -> In-Scope | N14: =IF($A14="","","In-Scope") -> In-Scope | O14: =IF($A14="","","In-Scope") -> In-Scope | P14: =IF($A14="","","In-Scope") -> In-Scope | Q14: =IF($A14="","","In-Scope") -> In-Scope | R14: =IF($A14="","","In-Scope") -> In-Scope | S14: =IF($A14="","","In-Scope") -> In-Scope | V14: =IF($A14="","","In-Scope") -> In-Scope | W14: =IF($A14="","","In-Scope") -> In-Scope | X14: =IF($A14="","","In-Scope") -> In-Scope | Y14: =IF($A14="","","In-Scope") -> In-Scope | Z14: =IF($A14="","","In-Scope") -> In-Scope | AA14: =IF($A14="","","In-Scope") -> In-Scope | AB14: =IF($A14="","","In-Scope") -> In-Scope | AC14: =IF($A14="","","In-Scope") -> In-Scope | ... AO14: =IF($A14="","","In-Scope") -> In-Scope
A15: IllinoisIndiana Project | B15: =IF($A15="","","In-Scope") -> In-Scope | C15: =IF($A15="","","In-Scope") -> In-Scope | D15: =IF($A15="","","In-Scope") -> In-Scope | E15: =IF($A15="","","In-Scope") -> In-Scope | F15: =IF($A15="","","In-Scope") -> In-Scope | G15: =IF($A15="","","In-Scope") -> In-Scope | H15: =IF($A15="","","In-Scope") -> In-Scope | I15: =IF($A15="","","Out-of-Scope") -> Out-of-Scope | J15: =IF($A15="","","Out-of-Scope") -> Out-of-Scope | K15: =IF($A15="","","In-Scope") -> In-Scope | L15: =IF($A15="","","Out-of-Scope") -> Out-of-Scope | M15: =IF($A15="","","In-Scope") -> In-Scope | N15: =IF($A15="","","In-Scope") -> In-Scope | O15: =IF($A15="","","In-Scope") -> In-Scope | P15: =IF($A15="","","In-Scope") -> In-Scope | Q15: =IF($A15="","","In-Scope") -> In-Scope | R15: =IF($A15="","","In-Scope") -> In-Scope | S15: =IF($A15="","","In-Scope") -> In-Scope | V15: =IF($A15="","","In-Scope") -> In-Scope | W15: =IF($A15="","","In-Scope") -> In-Scope | X15: =IF($A15="","","In-Scope") -> In-Scope | Y15: =IF($A15="","","In-Scope") -> In-Scope | Z15: =IF($A15="","","In-Scope") -> In-Scope | AA15: =IF($A15="","","In-Scope") -> In-Scope | AB15: =IF($A15="","","In-Scope") -> In-Scope | AC15: =IF($A15="","","In-Scope") -> In-Scope | ... AO15: =IF($A15="","","In-Scope") -> In-Scope
A16: New Mexico Project | B16: =IF($A16="","","In-Scope") -> In-Scope | C16: =IF($A16="","","In-Scope") -> In-Scope | D16: =IF($A16="","","In-Scope") -> In-Scope | E16: =IF($A16="","","In-Scope") -> In-Scope | F16: =IF($A16="","","Out-of-Scope") -> Out-of-Scope | G16: =IF($A16="","","In-Scope") -> In-Scope | H16: =IF($A16="","","In-Scope") -> In-Scope | I16: =IF($A16="","","Out-of-Scope") -> Out-of-Scope | J16: =IF($A16="","","Out-of-Scope") -> Out-of-Scope | K16: =IF($A16="","","In-Scope") -> In-Scope | L16: =IF($A16="","","Out-of-Scope") -> Out-of-Scope | M16: =IF($A16="","","In-Scope") -> In-Scope | N16: =IF($A16="","","In-Scope") -> In-Scope | O16: =IF($A16="","","In-Scope") -> In-Scope | P16: =IF($A16="","","In-Scope") -> In-Scope | Q16: =IF($A16="","","In-Scope") -> In-Scope | R16: =IF($A16="","","In-Scope") -> In-Scope | S16: =IF($A16="","","In-Scope") -> In-Scope | T16: RDM: The client contracted with a 3rd party to gneerate and manage the requirements | V16: =IF($A16="","","In-Scope") -> In-Scope | W16: =IF($A16="","","In-Scope") -> In-Scope | X16: =IF($A16="","","In-Scope") -> In-Scope | Y16: =IF($A16="","","In-Scope") -> In-Scope | Z16: =IF($A16="","","In-Scope") -> In-Scope | AA16: =IF($A16="","","In-Scope") -> In-Scope | AB16: =IF($A16="","","In-Scope") -> In-Scope | AC16: =IF($A16="","","In-Scope") -> In-Scope | ... AO16: =IF($A16="","","In-Scope") -> In-Scope
A17: Kentucky Project | B17: =IF($A17="","","In-Scope") -> In-Scope | C17: =IF($A17="","","In-Scope") -> In-Scope | D17: =IF($A17="","","In-Scope") -> In-Scope | E17: =IF($A17="","","In-Scope") -> In-Scope | F17: =IF($A17="","","In-Scope") -> In-Scope | G17: =IF($A17="","","In-Scope") -> In-Scope | H17: =IF($A17="","","In-Scope") -> In-Scope | I17: =IF($A17="","","Out-of-Scope") -> Out-of-Scope | J17: =IF($A17="","","Out-of-Scope") -> Out-of-Scope | K17: =IF($A17="","","In-Scope") -> In-Scope | L17: =IF($A17="","","Out-of-Scope") -> Out-of-Scope | M17: =IF($A17="","","In-Scope") -> In-Scope | N17: =IF($A17="","","In-Scope") -> In-Scope | O17: =IF($A17="","","In-Scope") -> In-Scope | P17: =IF($A17="","","In-Scope") -> In-Scope | Q17: =IF($A17="","","In-Scope") -> In-Scope | R17: =IF($A17="","","In-Scope") -> In-Scope | S17: =IF($A17="","","In-Scope") -> In-Scope | V17: =IF($A17="","","In-Scope") -> In-Scope | W17: =IF($A17="","","In-Scope") -> In-Scope | X17: =IF($A17="","","In-Scope") -> In-Scope | Y17: =IF($A17="","","In-Scope") -> In-Scope | Z17: =IF($A17="","","In-Scope") -> In-Scope | AA17: =IF($A17="","","In-Scope") -> In-Scope | AB17: =IF($A17="","","In-Scope") -> In-Scope | AC17: =IF($A17="","","In-Scope") -> In-Scope | ... AO17: =IF($A17="","","In-Scope") -> In-Scope
A18: MontanaNebraska Project | B18: =IF($A18="","","In-Scope") -> In-Scope | C18: =IF($A18="","","In-Scope") -> In-Scope | D18: =IF($A18="","","In-Scope") -> In-Scope | E18: =IF($A18="","","In-Scope") -> In-Scope | F18: =IF($A18="","","In-Scope") -> In-Scope | G18: =IF($A18="","","In-Scope") -> In-Scope | H18: =IF($A18="","","In-Scope") -> In-Scope | I18: =IF($A18="","","Out-of-Scope") -> Out-of-Scope | J18: =IF($A18="","","Out-of-Scope") -> Out-of-Scope | K18: =IF($A18="","","In-Scope") -> In-Scope | L18: =IF($A18="","","Out-of-Scope") -> Out-of-Scope | M18: =IF($A18="","","In-Scope") -> In-Scope | N18: =IF($A18="","","In-Scope") -> In-Scope | O18: =IF($A18="","","In-Scope") -> In-Scope | P18: =IF($A18="","","In-Scope") -> In-Scope | Q18: =IF($A18="","","In-Scope") -> In-Scope | R18: =IF($A18="","","In-Scope") -> In-Scope | S18: =IF($A18="","","In-Scope") -> In-Scope | V18: =IF($A18="","","In-Scope") -> In-Scope | W18: =IF($A18="","","In-Scope") -> In-Scope | X18: =IF($A18="","","In-Scope") -> In-Scope | Y18: =IF($A18="","","In-Scope") -> In-Scope | Z18: =IF($A18="","","In-Scope") -> In-Scope | AA18: =IF($A18="","","In-Scope") -> In-Scope | AB18: =IF($A18="","","In-Scope") -> In-Scope | AC18: =IF($A18="","","In-Scope") -> In-Scope | ... AO18: =IF($A18="","","In-Scope") -> In-Scope
A19: Arkansas Project | B19: =IF($A19="","","In-Scope") -> In-Scope | C19: =IF($A19="","","In-Scope") -> In-Scope | D19: =IF($A19="","","In-Scope") -> In-Scope | E19: =IF($A19="","","In-Scope") -> In-Scope | F19: =IF($A19="","","In-Scope") -> In-Scope | G19: =IF($A19="","","In-Scope") -> In-Scope | H19: =IF($A19="","","In-Scope") -> In-Scope | I19: =IF($A19="","","Out-of-Scope") -> Out-of-Scope | J19: =IF($A19="","","Out-of-Scope") -> Out-of-Scope | K19: =IF($A19="","","In-Scope") -> In-Scope | L19: =IF($A19="","","Out-of-Scope") -> Out-of-Scope | M19: =IF($A19="","","In-Scope") -> In-Scope | N19: =IF($A19="","","In-Scope") -> In-Scope | O19: =IF($A19="","","In-Scope") -> In-Scope | P19: =IF($A19="","","In-Scope") -> In-Scope | Q19: =IF($A19="","","In-Scope") -> In-Scope | R19: =IF($A19="","","In-Scope") -> In-Scope | S19: =IF($A19="","","In-Scope") -> In-Scope | V19: =IF($A19="","","In-Scope") -> In-Scope | W19: =IF($A19="","","In-Scope") -> In-Scope | X19: =IF($A19="","","In-Scope") -> In-Scope | Y19: =IF($A19="","","In-Scope") -> In-Scope | Z19: =IF($A19="","","In-Scope") -> In-Scope | AA19: =IF($A19="","","In-Scope") -> In-Scope | AB19: =IF($A19="","","In-Scope") -> In-Scope | AC19: =IF($A19="","","In-Scope") -> In-Scope | ... AO19: =IF($A19="","","In-Scope") -> In-Scope
A20: Alabama Project | B20: =IF($A20="","","In-Scope") -> In-Scope | C20: =IF($A20="","","In-Scope") -> In-Scope | D20: =IF($A20="","","In-Scope") -> In-Scope | E20: =IF($A20="","","In-Scope") -> In-Scope | F20: =IF($A20="","","In-Scope") -> In-Scope | G20: =IF($A20="","","In-Scope") -> In-Scope | H20: =IF($A20="","","In-Scope") -> In-Scope | I20: =IF($A20="","","Out-of-Scope") -> Out-of-Scope | J20: =IF($A20="","","Out-of-Scope") -> Out-of-Scope | K20: =IF($A20="","","In-Scope") -> In-Scope | L20: =IF($A20="","","Out-of-Scope") -> Out-of-Scope | M20: =IF($A20="","","In-Scope") -> In-Scope | N20: =IF($A20="","","In-Scope") -> In-Scope | O20: =IF($A20="","","In-Scope") -> In-Scope | P20: =IF($A20="","","In-Scope") -> In-Scope | Q20: =IF($A20="","","In-Scope") -> In-Scope | R20: =IF($A20="","","In-Scope") -> In-Scope | S20: =IF($A20="","","In-Scope") -> In-Scope | V20: =IF($A20="","","In-Scope") -> In-Scope | W20: =IF($A20="","","In-Scope") -> In-Scope | X20: =IF($A20="","","In-Scope") -> In-Scope | Y20: =IF($A20="","","In-Scope") -> In-Scope | Z20: =IF($A20="","","In-Scope") -> In-Scope | AA20: =IF($A20="","","In-Scope") -> In-Scope | AB20: =IF($A20="","","In-Scope") -> In-Scope | AC20: =IF($A20="","","In-Scope") -> In-Scope | ... AO20: =IF($A20="","","In-Scope") -> In-Scope
